Workbook

Sheet 差し替え品番
B1: ＊金額順
B2: 2024年在庫確保品番 | E2: 2026年 | G2: 2025年7月 確保数改修
C3: 変更前（24年9月まで） | D3: 変更後（24年10月以降） | E3: 変更後（26年8月以降） | G3: 品番 | H3: 改修前 | I3: 改修後 | J3: 内容
B4: 1 | C4: fisi-05 | D4: fisi-05 | E4: si-05 | F4: 3250 | G4: fisi-05 | H4: 3315 | I4: 3500 | J4: amazon販売増に伴い、伸び率を前期130%に再調整
B5: 2 | C5: si-07 | D5: flm-001 | E5: flc-002 | F5: 2186 | G5: flm-001 | H5: 1899 | I5: 2200 | J5: amazon販売増に伴い、伸び率を前期120%に再調整
B6: 3 | C6: flc-002 | D6: fll-006 | E6: flm-001 | F6: 2218 | G6: si-10 | H6: 898 | I6: 1000 | J6: 在庫切れ無し（転換率を昨年平均）で計算した場合、伸び率を前期120%が見込めるため再調整
B7: 4 | C7: flm-006 | D7: flm-006 | E7: fll-3004 | F7: 2325 | G7: si-13 | H7: 507 | I7: 1100 | J7: 今期販売の伸びがUP。今期の視覚化データの想定に合わせ再調整
B8: 5 | C8: flm-001 | D8: flm-002 | E8: fll-006 | F8: 1881 | G8: 5135(5336p) | H8: 955 | I8: 1550 | J8: 今期販売の伸びがUP。今期の視覚化データの想定に合わせ再調整
B9: 6 | C9: fll-006 | D9: flc-002 | E9: si-13 | F9: 1022 | G9: ph5099 | H9: 670 | I9: 1000 | J9: 今期販売の伸びがUP。今期の視覚化データの想定に合わせ再調整
B10: 7 | C10: si-01sa | D10: si-10 | E10: si-13ph(併せて発注のため繰り上げ) | F10: 506
B11: 8 | C11: spc-007 | D11: si-13（si-13PH） | E11: si-01sa | F11: 1503
B12: 9 | C12: bdr-1002 | D12: spc-007 | E12: ph5099 | F12: 1721
B13: 10 | C13: si-09 | D13: si-01sa（si-01sap） | E13: flm-006 | F13: 1294
B14: 11 | C14: gg5099 | D14: fll-3004 | E14: flm-002 | F14: 1368
B15: 12 | C15: bdr-1003 | D15: si-07 | E15: si-10 | F15: 973
B16: 13 | C16: si-10 | D16: gg5099 | E16: spc-007 | F16: 1243
B17: 14 | C17: si-08r | D17: fll-3000 | E17: flh-001ph | F17: 623
B18: 15 | C18: flm-002 | D18: flh-001ph | E18: fll-3000 | F18: 1052
B19: 16 | C19: si-03 | D19: si-09 | E19: flk-001 | F19: 597
B20: 17 | C20: 5135(5336P) | D20: bdr-1002 | E20: fl-3000 | F20: 1817 | G20: ＊状況を見て年間販売想定数を更新する必要有り
B21: 18 | C21: gg3087 | D21: bdr-1003 | E21: si-09 | F21: 805
B22: 19 | C22: fll-3000 | D22: 5135(5336P) | E22: spc-006 | F22: 691
B23: 20 | C23: flr-001 | D23: ph5099 | E23: fll-4000 | F23: 757 | G23: ＊状況を見て年間販売想定数を更新する必要有り
B24: 21 | C24: spc-008 | D24: si-08（si-08r） | E24: flw-001-002 | F24: 350
E25: si-11 | F25: 448
E26: si-08r | F26: 341
B31: 選定除外品番
B32: 選定追加品番
B33: 念の為在庫確認品番

Sheet 在庫推移 (2026.08～)
U1: 欠品
C2: ＊FL-3000の在庫も確認する！（次回発注あるかどうか：振り分け表にて） | AH2: 欠品 | AN2: 7月確認月 | AS2: 入荷済み | AV2: 仕様替え | CI2: 仕様替え | CK2: 納期変更分 | CM2: 入荷済み
C3: 在庫確保による販売試算表 | H3: 2025年12月変更分 | J3: 46224 | AN3: ↓ | BK3: プライムデー | BQ3: プライム感謝祭 | BS3: ブラックフライデー | BU3: スーパーセール
C4: 売上上位品番 | F4: 2024年販売想定ベース | H4: 調整データ | J4: 在庫確保数 | AH4: 補充完了日 | AS4: 45566 | AU4: 45597 | AW4: 45627 | AY4: 45658 | BA4: 45689 | BC4: 45717 | BE4: 45748 | BG4: 45778 | BI4: 45809 | BK4: 45839 | BM4: 45870 | BO4: 45901 | BQ4: 45931 | BS4: 45962 | BU4: 45992 | BW4: 46023 | BY4: 46054 | CA4: 46082 | CC4: 46113 | CE4: 46143 | CG4: 46174 | CI4: 46204 | CK4: 46235 | CM4: 46266 | CO4: 46296 | CQ4: 46327 | CS4: 46357 | CU4: 46388 | CW4: 46054 | CY4: 46082
B5: 優先順位 | C5: 品番 | D5: カラー | E5: 度数 | F5: 年間販売数 | G5: 年間売上額 | H5: 年間販売想定数 | I5: 年間売上想定額 | J5: フリー在庫 | K5: EC合計 | L5: 楽天・Yahoo!・auPAY(RSL) | M5: Amazon(FBA) | N5: ECストック | O5: 10/17~ | P5: 11月 | Q5: 12月 | R5: 1月 | S5: 2月 | T5: 3月 | U5: 4月 | V5: 5月 | W5: 6月 | X5: 7月 | Y5: 8月 | Z5: 9月 | AA5: 10月 | AB5: 11月 | AC5: 12月 | AD5: 1月 | AE5: 2月 | AF5: 3月 | AG5: 4月 | AH5: 5月 | AI5: 7月 | AJ5: 8月 | AK5: 9月 | AL5: 10月 | AM5: 11月 | AN5: 12月 | AO5: 1月 | AP5: 2月 | AQ5: 3月 | AS5: 必要数 | AT5: 入荷品確保 | AU5: 必要数 | AV5: 入荷品確保 | AW5: 必要数 | AX5: 入荷品確保 | AY5: 必要数 | AZ5: 入荷品確保 | BA5: 必要数 | BB5: 入荷品確保 | BC5: 必要数 | BD5: 入荷品確保 | BE5: 必要数 | BF5: 入荷品確保 | BG5: 必要数 | BH5: 入荷品確保 | BI5: 必要数 | BJ5: 入荷品確保 | BK5: 必要数 | BL5: 入荷品確保 | BM5: 必要数 | BN5: 入荷品確保 | BO5: 必要数 | BP5: 入荷品確保 | BQ5: 必要数 | BR5: 入荷品確保 | BS5: 必要数 | BT5: 入荷品確保 | BU5: 必要数 | BV5: 入荷品確保 | BW5: 必要数 | BX5: 入荷品確保 | BY5: 必要数 | BZ5: 入荷品確保 | CA5: 必要数 | CB5: 入荷品確保 | CC5: 必要数 | CD5: 入荷品確保 | CE5: 必要数 | CF5: 入荷品確保 | CG5: 必要数 | CH5: 入荷品確保 | CI5: 必要数 | CJ5: 入荷品確保 | CK5: 必要数 | CL5: 入荷品確保 | CM5: 必要数 | CN5: 入荷品確保 | CO5: 必要数 | CP5: 入荷品確保 | CQ5: 必要数 | CR5: 入荷品確保 | CS5: 必要数 | CT5: 入荷品確保 | CU5: 必要数 | CV5: 入荷品確保 | CW5: 必要数 | CX5: 入荷品確保 | CY5: 必要数 | CZ5: 入荷品確保
B6: 1 | C6: fisi-05 ＊欲しい月の2カ月前入荷想定で考える | F6: =SUM(F7:F26) -> 1314 | G6: =SUM(G7:G26) -> 5781600 | H6: 3500 | I6: =SUM(I7:I26) -> 15400000 | J6: =SUM(J7:J26) -> 95 | K6: =SUM(K7:K26) -> 876 | L6: =SUM(L7:L26) -> 123 | M6: =SUM(M7:M26) -> 55 | N6: =SUM(N7:N26) -> 698 | AS6: =SUM(AS7:AS26) -> 350 | AT6: =SUM(AT7:AT26) -> 0 | AU6: =SUM(AU7:AU26) -> 315 | AV6: =SUM(AV7:AV26) -> 432 | AW6: =SUM(AW7:AW26) -> 350 | AX6: =SUM(AX7:AX26) -> 784 | AY6: =SUM(AY7:AY26) -> 213.13031 | AZ6: =SUM(AZ7:AZ26) -> 0 | ... CZ6: =SUM(CZ7:CZ26) -> 0
C7: 入荷： 7月 1210枚 8月 600枚 11月 600枚 | D7: 1 | E7: +1.00 | F7: 48 | G7: =F7*4400 -> 211200 | H7: =F7*($H$6/$F$6) -> 127.85388 | I7: =H7*4400 -> 562557.08 | J7: 3 | K7: =SUM(L7:N7) -> 35 | L7: 10 | M7: 0 | N7: 25 | P7: 45622 | Q7: 45646 | V7: 45792 | Y7: 45884 | AC7: 45662 | AI7: =SUM(J7:K7)-CI7+CJ7 -> 47.771689 | AJ7: =AI7-CK7+CL7 -> 63.033479 | AK7: =AJ7-CM7+CN7 -> 47.691013 | AL7: =AK7-CO7+CP7 -> 34.905625 | AM7: =AL7-CQ7+CR7 -> 48.398775 | AN7: =AM7-CS7+CT7 -> 35.613387 | AO7: =AN7-CU7+CV7 -> 27.827805 | AP7: =AO7-CW7+CX7 -> 20.716173 | AQ7: =AP7-CY7+CZ7 -> 10.487863 | AS7: =$H$7*月別販売比率!AG5 -> 12.785388 | AU7: =$H$7*月別販売比率!AL5 -> 11.506849 | AV7: 12 | AW7: =$H$7*月別販売比率!AQ5 -> 12.785388 | AX7: 46 | AY7: =$H$7*月別販売比率!AV5 -> 7.7855823 | BA7: =$H$7*月別販売比率!BA5 -> 7.1116319 | BB7: 10 | BC7: =$H$7*月別販売比率!BF5 -> 10.228311 | BE7: =$H$7*月別販売比率!C21 -> 9.0602695 | BG7: =$H$7*月別販売比率!H21 -> 8.9497717 | BH7: 26 | BI7: =$H$7*月別販売比率!M21 -> 12.921385 | BJ7: 30 | BK7: =$H$7*月別販売比率!R21 -> 10.228311 | BM7: =$H$7*月別販売比率!W21 -> 9.7382108 | BN7: 25 | BO7: =$H$7*月別販売比率!AB21 -> 15.342466 | BP7: 20 | BQ7: =$H$7*月別販売比率!AG21 -> 12.785388 | BS7: =$H$7*月別販売比率!AL21 -> 11.506849 | BT7: 40 | BU7: =$H$7*月別販売比率!AQ21 -> 12.785388 | BV7: 10 | BW7: =$H$7*月別販売比率!AV21 -> 7.7855823 | BY7: =$H$7*月別販売比率!BA21 -> 7.1116319 | BZ7: 20 | CA7: =$H$7*月別販売比率!BF21 -> 10.228311 | CC7: =H7*月別販売比率!$C$21 -> 9.0602695 | CE7: =H7*月別販売比率!$H$21 -> 8.9497717 | CF7: 30 | CG7: =$H$7*月別販売比率!M21 -> 12.921385 | CH7: 25 | CI7: =H7*月別販売比率!$R$21 -> 10.228311 | CJ7: 20 | CK7: =H7*月別販売比率!$W$21 -> 9.7382108 | CL7: 25 | CM7: =H7*月別販売比率!$AB$21 -> 15.342466 | CO7: =H7*月別販売比率!$AG$21 -> 12.785388 | CQ7: =H7*月別販売比率!$AL$21 -> 11.506849 | CR7: 25 | CS7: =H7*月別販売比率!$AQ$21 -> 12.785388 | CU7: =H7*月別販売比率!$AV$21 -> 7.7855823 | CW7: =H7*月別販売比率!$BA$21 -> 7.1116319 | CY7: =H7*月別販売比率!$BF$21 -> 10.228311
E8: +1.50 | F8: 144 | G8: =F8*4400 -> 633600 | H8: =F8*($H$6/$F$6) -> 383.56164 | I8: =H8*4400 -> 1687671.2 | J8: 5 | K8: =SUM(L8:N8) -> 85 | L8: 10 | M8: 5 | N8: 70 | P8: 45622 | Q8: 45646 | AB8: 45979 | AI8: =SUM(J8:K8)-CI8+CJ8 -> 124.31507 | AJ8: =AI8-CK8+CL8 -> 185.10044 | AK8: =AJ8-CM8+CN8 -> 139.07304 | AL8: =AK8-CO8+CP8 -> 100.71687 | AM8: =AL8-CQ8+CR8 -> 131.19633 | AN8: =AM8-CS8+CT8 -> 92.840162 | AO8: =AN8-CU8+CV8 -> 69.483415 | AP8: =AO8-CW8+CX8 -> 48.14852 | AQ8: =AP8-CY8+CZ8 -> 17.463588 | AS8: =$H$8*月別販売比率!AG5 -> 38.356164 | AU8: =$H$8*月別販売比率!AL5 -> 34.520548 | AV8: 37 | AW8: =$H$8*月別販売比率!AQ5 -> 38.356164 | AX8: 81 | AY8: =$H$8*月別販売比率!AV5 -> 23.356747 | BA8: =$H$8*月別販売比率!BA5 -> 21.334896 | BB8: 75 | BC8: =$H$8*月別販売比率!BF5 -> 30.684932 | BE8: =$H$8*月別販売比率!C21 -> 27.180809 | BG8: =$H$8*月別販売比率!H21 -> 26.849315 | BH8: 50 | BI8: =$H$8*月別販売比率!M21 -> 38.764155 | BJ8: 55 | BK8: =$H$8*月別販売比率!R21 -> 30.684932 | BM8: =$H$8*月別販売比率!W21 -> 29.214632 | BN8: 30 | BO8: =$H$8*月別販売比率!AB21 -> 46.027397 | BP8: 50 | BQ8: =$H$8*月別販売比率!AG21 -> 38.356164 | BR8: 79 | BS8: =$H$8*月別販売比率!AL21 -> 34.520548 | BT8: 85 | BU8: =$H$8*月別販売比率!AQ21 -> 38.356164 | BV8: 50 | BW8: =$H$8*月別販売比率!AV21 -> 23.356747 | BY8: =$H$8*月別販売比率!BA21 -> 21.334896 | BZ8: 8 | CA8: =$H$8*月別販売比率!BF21 -> 30.684932 | CC8: =H8*月別販売比率!$C$21 -> 27.180809 | CE8: =H8*月別販売比率!$H$21 -> 26.849315 | CF8: 80 | CG8: =$H$8*月別販売比率!M21 -> 38.764155 | CH8: 70 | CI8: =H8*月別販売比率!$R$21 -> 30.684932 | CJ8: 65 | CK8: =H8*月別販売比率!$W$21 -> 29.214632 | CL8: 90 | CM8: =H8*月別販売比率!$AB$21 -> 46.027397 | CO8: =H8*月別販売比率!$AG$21 -> 38.356164 | CQ8: =H8*月別販売比率!$AL$21 -> 34.520548 | CR8: 65 | CS8: =H8*月別販売比率!$AQ$21 -> 38.356164 | CU8: =H8*月別販売比率!$AV$21 -> 23.356747 | CW8: =H8*月別販売比率!$BA$21 -> 21.334896 | CY8: =H8*月別販売比率!$BF$21 -> 30.684932
E9: +2.00 | F9: 127 | G9: =F9*4400 -> 558800 | H9: =F9*($H$6/$F$6) -> 338.28006 | I9: =H9*4400 -> 1488432.3 | J9: 29 | K9: =SUM(L9:N9) -> 134 | L9: 9 | M9: 15 | N9: 110 | P9: 45622 | AB9: 45979 | AI9: =SUM(J9:K9)-CI9+CJ9 -> 160.9376 | AJ9: =AI9-CK9+CL9 -> 200.17191 | AK9: =AJ9-CM9+CN9 -> 159.57831 | AL9: =AK9-CO9+CP9 -> 125.7503 | AM9: =AL9-CQ9+CR9 -> 140.30509 | AN9: =AM9-CS9+CT9 -> 106.47709 | AO9: =AN9-CU9+CV9 -> 85.877734 | AP9: =AO9-CW9+CX9 -> 67.061542 | AQ9: =AP9-CY9+CZ9 -> 39.999137 | AS9: =$H$9*月別販売比率!AG5 -> 33.828006 | AU9: =$H$9*月別販売比率!AL5 -> 30.445205 | AV9: 55 | AW9: =$H$9*月別販売比率!AQ5 -> 33.828006 | AX9: 71 | AY9: =$H$9*月別販売比率!AV5 -> 20.599353 | BA9: =$H$9*月別販売比率!BA5 -> 18.816193 | BB9: 65 | BC9: =$H$9*月別販売比率!BF5 -> 27.062405 | BE9: =$H$9*月別販売比率!C21 -> 23.971963 | BG9: =$H$9*月別販売比率!H21 -> 23.679604 | BH9: 45 | BI9: =$H$9*月別販売比率!M21 -> 34.187831 | BJ9: 45 | BK9: =$H$9*月別販売比率!R21 -> 27.062405 | BM9: =$H$9*月別販売比率!W21 -> 25.765683 | BN9: 10 | BO9: =$H$9*月別販売比率!AB21 -> 40.593607 | BQ9: =$H$9*月別販売比率!AG21 -> 33.828006 | BR9: 90 | BS9: =$H$9*月別販売比率!AL21 -> 30.445205 | BT9: 48 | BU9: =$H$9*月別販売比率!AQ21 -> 33.828006 | BV9: 25 | BW9: =$H$9*月別販売比率!AV21 -> 20.599353 | BY9: =$H$9*月別販売比率!BA21 -> 18.816193 | BZ9: 8 | CA9: =$H$9*月別販売比率!BF21 -> 27.062405 | CC9: =H9*月別販売比率!$C$21 -> 23.971963 | CE9: =H9*月別販売比率!$H$21 -> 23.679604 | CF9: 100 | CG9: =$H$9*月別販売比率!M21 -> 34.187831 | CH9: 65 | CI9: =H9*月別販売比率!$R$21 -> 27.062405 | CJ9: 25 | CK9: =H9*月別販売比率!$W$21 -> 25.765683 | CL9: 65 | CM9: =H9*月別販売比率!$AB$21 -> 40.593607 | CO9: =H9*月別販売比率!$AG$21 -> 33.828006 | CQ9: =H9*月別販売比率!$AL$21 -> 30.445205 | CR9: 45 | CS9: =H9*月別販売比率!$AQ$21 -> 33.828006 | CU9: =H9*月別販売比率!$AV$21 -> 20.599353 | CW9: =H9*月別販売比率!$BA$21 -> 18.816193 | CY9: =H9*月別販売比率!$BF$21 -> 27.062405
E10: +2.50 | F10: 46 | G10: =F10*4400 -> 202400 | H10: =F10*($H$6/$F$6) -> 122.52664 | I10: =H10*4400 -> 539117.2 | J10: 23 | K10: =SUM(L10:N10) -> 35 | L10: 10 | M10: 0 | N10: 25 | P10: 45622 | V10: 45792 | Y10: 45884 | AC10: 46017 | AI10: =SUM(J10:K10)-CI10+CJ10 -> 68.197869 | AJ10: =AI10-CK10+CL10 -> 78.865417 | AK10: =AJ10-CM10+CN10 -> 64.162221 | AL10: =AK10-CO10+CP10 -> 51.909557 | AM10: =AL10-CQ10+CR10 -> 60.88216 | AN10: =AM10-CS10+CT10 -> 48.629496 | AO10: =AN10-CU10+CV10 -> 41.168313 | AP10: =AO10-CW10+CX10 -> 34.352999 | AQ10: =AP10-CY10+CZ10 -> 24.550868 | AS10: =$H$10*月別販売比率!AG5 -> 12.252664 | AU10: =$H$10*月別販売比率!AL5 -> 11.027397 | AV10: 20 | AW10: =$H$10*月別販売比率!AQ5 -> 12.252664 | AX10: 26 | AY10: =$H$10*月別販売比率!AV5 -> 7.461183 | BA10: =$H$10*月別販売比率!BA5 -> 6.8153139 | BB10: 20 | BC10: =$H$10*月別販売比率!BF5 -> 9.8021309 | BE10: =$H$10*月別販売比率!C21 -> 8.6827583 | BG10: =$H$10*月別販売比率!H21 -> 8.5768645 | BH10: 20 | BI10: =$H$10*月別販売比率!M21 -> 12.382994 | BJ10: 20 | BK10: =$H$10*月別販売比率!R21 -> 9.8021309 | BM10: =$H$10*月別販売比率!W21 -> 9.332452 | BN10: 10 | BO10: =$H$10*月別販売比率!AB21 -> 14.703196 | BP10: 35 | BQ10: =$H$10*月別販売比率!AG21 -> 12.252664 | BS10: =$H$10*月別販売比率!AL21 -> 11.027397 | BT10: 17 | BU10: =$H$10*月別販売比率!AQ21 -> 12.252664 | BV10: 10 | BW10: =$H$10*月別販売比率!AV21 -> 7.461183 | BY10: =$H$10*月別販売比率!BA21 -> 6.8153139 | BZ10: 23 | CA10: =$H$10*月別販売比率!BF21 -> 9.8021309 | CC10: =H10*月別販売比率!$C$21 -> 8.6827583 | CE10: =H10*月別販売比率!$H$21 -> 8.5768645 | CF10: 30 | CG10: =$H$10*月別販売比率!M21 -> 12.382994 | CH10: 25 | CI10: =H10*月別販売比率!$R$21 -> 9.8021309 | CJ10: 20 | CK10: =H10*月別販売比率!$W$21 -> 9.332452 | CL10: 20 | CM10: =H10*月別販売比率!$AB$21 -> 14.703196 | CO10: =H10*月別販売比率!$AG$21 -> 12.252664 | CQ10: =H10*月別販売比率!$AL$21 -> 11.027397 | CR10: 20 | CS10: =H10*月別販売比率!$AQ$21 -> 12.252664 | CU10: =H10*月別販売比率!$AV$21 -> 7.461183 | CW10: =H10*月別販売比率!$BA$21 -> 6.8153139 | CY10: =H10*月別販売比率!$BF$21 -> 9.8021309
E11: +3.00 | F11: 30 | G11: =F11*4400 -> 132000 | H11: =F11*($H$6/$F$6) -> 79.908676 | I11: =H11*4400 -> 351598.17 | J11: 0 | K11: =SUM(L11:N11) -> 31 | L11: 7 | M11: 0 | N11: 24 | S11: 45707 | V11: 45792 | AI11: =SUM(J11:K11)-CI11+CJ11 -> 24.607306 | AJ11: =AI11-CK11+CL11 -> 33.520924 | AK11: =AJ11-CM11+CN11 -> 23.931883 | AL11: =AK11-CO11+CP11 -> 15.941015 | AM11: =AL11-CQ11+CR11 -> 23.749235 | AN11: =AM11-CS11+CT11 -> 15.758367 | AO11: =AN11-CU11+CV11 -> 10.892378 | AP11: =AO11-CW11+CX11 -> 6.4476083 | AQ11: =AP11-CY11+CZ11 -> 0.054914204 | AS11: =$H$11*月別販売比率!AG5 -> 7.9908676 | AU11: =$H$11*月別販売比率!AL5 -> 7.1917808 | AW11: =$H$11*月別販売比率!AQ5 -> 7.9908676 | AY11: =$H$11*月別販売比率!AV5 -> 4.8659889 | BA11: =$H$11*月別販売比率!BA5 -> 4.4447699 | BB11: 15 | BC11: =$H$11*月別販売比率!BF5 -> 6.3926941 | BE11: =$H$11*月別販売比率!C21 -> 5.6626685 | BG11: =$H$11*月別販売比率!H21 -> 5.5936073 | BH11: 10 | BI11: =$H$11*月別販売比率!M21 -> 8.0758656 | BJ11: 10 | BK11: =$H$11*月別販売比率!R21 -> 6.3926941 | BM11: =$H$11*月別販売比率!W21 -> 6.0863818 | BN11: 10 | BO11: =$H$11*月別販売比率!AB21 -> 9.5890411 | BP11: 20 | BQ11: =$H$11*月別販売比率!AG21 -> 7.9908676 | BS11: =$H$11*月別販売比率!AL21 -> 7.1917808 | BT11: 30 | BU11: =$H$11*月別販売比率!AQ21 -> 7.9908676 | BV11: 5 | BW11: =$H$11*月別販売比率!AV21 -> 4.8659889 | BY11: =$H$11*月別販売比率!BA21 -> 4.4447699 | BZ11: 5 | CA11: =$H$11*月別販売比率!BF21 -> 6.3926941 | CC11: =H11*月別販売比率!$C$21 -> 5.6626685 | CE11: =H11*月別販売比率!$H$21 -> 5.5936073 | CF11: 20 | CG11: =$H$11*月別販売比率!M21 -> 8.0758656 | CH11: 24 | CI11: =H11*月別販売比率!$R$21 -> 6.3926941 | CK11: =H11*月別販売比率!$W$21 -> 6.0863818 | CL11: 15 | CM11: =H11*月別販売比率!$AB$21 -> 9.5890411 | CO11: =H11*月別販売比率!$AG$21 -> 7.9908676 | CQ11: =H11*月別販売比率!$AL$21 -> 7.1917808 | CR11: 15 | CS11: =H11*月別販売比率!$AQ$21 -> 7.9908676 | CU11: =H11*月別販売比率!$AV$21 -> 4.8659889 | CW11: =H11*月別販売比率!$BA$21 -> 4.4447699 | CY11: =H11*月別販売比率!$BF$21 -> 6.3926941
D12: 2 | E12: +1.00 | F12: 84 | G12: =F12*4400 -> 369600 | H12: =F12*($H$6/$F$6) -> 223.74429 | I12: =H12*4400 -> 984474.89 | J12: 0 | K12: =SUM(L12:N12) -> 45 | L12: 0 | M12: 0 | N12: 45 | P12: 45622 | Q12: 45646 | V12: 45792 | Y12: 45884 | AB12: 45979 | AI12: =SUM(J12:K12)-CI12+CJ12 -> 82.100457 | AJ12: =AI12-CK12+CL12 -> 100.05859 | AK12: =AJ12-CM12+CN12 -> 73.209273 | AL12: =AK12-CO12+CP12 -> 50.834843 | AM12: =AL12-CQ12+CR12 -> 65.697857 | AN12: =AM12-CS12+CT12 -> 43.323428 | AO12: =AN12-CU12+CV12 -> 29.698659 | AP12: =AO12-CW12+CX12 -> 17.253303 | AQ12: =AP12-CY12+CZ12 -> -0.64624023 | AS12: =$H$12*月別販売比率!AG5 -> 22.374429 | AU12: =$H$12*月別販売比率!AL5 -> 20.136986 | AV12: 36 | AW12: =$H$12*月別販売比率!AQ5 -> 22.374429 | AX12: 60 | AY12: =$H$12*月別販売比率!AV5 -> 13.624769 | BA12: =$H$12*月別販売比率!BA5 -> 12.445356 | BB12: 35 | BC12: =$H$12*月別販売比率!BF5 -> 17.899543 | BE12: =$H$12*月別販売比率!C21 -> 15.855472 | BG12: =$H$12*月別販売比率!H21 -> 15.6621 | BH12: 27 | BI12: =$H$12*月別販売比率!M21 -> 22.612424 | BJ12: 20 | BK12: =$H$12*月別販売比率!R21 -> 17.899543 | BM12: =$H$12*月別販売比率!W21 -> 17.041869 | BN12: 35 | BO12: =$H$12*月別販売比率!AB21 -> 26.849315 | BP12: 30 | BQ12: =$H$12*月別販売比率!AG21 -> 22.374429 | BR12: 25 | BS12: =$H$12*月別販売比率!AL21 -> 20.136986 | BT12: 75 | BU12: =$H$12*月別販売比率!AQ21 -> 22.374429 | BV12: 35 | BW12: =$H$12*月別販売比率!AV21 -> 13.624769 | BY12: =$H$12*月別販売比率!BA21 -> 12.445356 | BZ12: 16 | CA12: =$H$12*月別販売比率!BF21 -> 17.899543 | CC12: =H12*月別販売比率!$C$21 -> 15.855472 | CE12: =H12*月別販売比率!$H$21 -> 15.6621 | CF12: 30 | CG12: =$H$12*月別販売比率!M21 -> 22.612424 | CH12: 45 | CI12: =H12*月別販売比率!$R$21 -> 17.899543 | CJ12: 55 | CK12: =H12*月別販売比率!$W$21 -> 17.041869 | CL12: 35 | CM12: =H12*月別販売比率!$AB$21 -> 26.849315 | CO12: =H12*月別販売比率!$AG$21 -> 22.374429 | CQ12: =H12*月別販売比率!$AL$21 -> 20.136986 | CR12: 35 | CS12: =H12*月別販売比率!$AQ$21 -> 22.374429 | CU12: =H12*月別販売比率!$AV$21 -> 13.624769 | CW12: =H12*月別販売比率!$BA$21 -> 12.445356 | CY12: =H12*月別販売比率!$BF$21 -> 17.899543
E13: +1.50 | F13: 116 | G13: =F13*4400 -> 510400 | H13: =F13*($H$6/$F$6) -> 308.98021 | I13: =H13*4400 -> 1359512.9 | J13: 0 | K13: =SUM(L13:N13) -> 29 | L13: 0 | M13: 0 | N13: 29 | P13: 45622 | Q13: 45646 | V13: 45792 | Y13: 45884 | AB13: 45979 | AC13: 45662 | AI13: =SUM(J13:K13)-CI13+CJ13 -> 98.281583 | AJ13: =AI13-CK13+CL13 -> 144.74757 | AK13: =AJ13-CM13+CN13 -> 107.66995 | AL13: =AK13-CO13+CP13 -> 76.771927 | AM13: =AL13-CQ13+CR13 -> 81.963707 | AN13: =AM13-CS13+CT13 -> 51.065686 | AO13: =AN13-CU13+CV13 -> 32.250529 | AP13: =AO13-CW13+CX13 -> 15.064085 | AQ13: =AP13-CY13+CZ13 -> -9.6543317 | AS13: =$H$13*月別販売比率!AG5 -> 30.898021 | AU13: =$H$13*月別販売比率!AL5 -> 27.808219 | AV13: 47 | AW13: =$H$13*月別販売比率!AQ5 -> 30.898021 | AX13: 115 | AY13: =$H$13*月別販売比率!AV5 -> 18.815157 | BA13: =$H$13*月別販売比率!BA5 -> 17.186444 | BB13: 40 | BC13: =$H$13*月別販売比率!BF5 -> 24.718417 | BE13: =$H$13*月別販売比率!C21 -> 21.895651 | BG13: =$H$13*月別販売比率!H21 -> 21.628615 | BH13: 35 | BI13: =$H$13*月別販売比率!M21 -> 31.22668 | BJ13: 25 | BK13: =$H$13*月別販売比率!R21 -> 24.718417 | BM13: =$H$13*月別販売比率!W21 -> 23.534009 | BN13: 80 | BO13: =$H$13*月別販売比率!AB21 -> 37.077626 | BQ13: =$H$13*月別販売比率!AG21 -> 30.898021 | BR13: 60 | BS13: =$H$13*月別販売比率!AL21 -> 27.808219 | BT13: 30 | BU13: =$H$13*月別販売比率!AQ21 -> 30.898021 | BV13: 45 | BW13: =$H$13*月別販売比率!AV21 -> 18.815157 | BY13: =$H$13*月別販売比率!BA21 -> 17.186444 | BZ13: 83 | CA13: =$H$13*月別販売比率!BF21 -> 24.718417 | CC13: =H13*月別販売比率!$C$21 -> 21.895651 | CE13: =H13*月別販売比率!$H$21 -> 21.628615 | CF13: 30 | CG13: =$H$13*月別販売比率!M21 -> 31.22668 | CH13: 29 | CI13: =H13*月別販売比率!$R$21 -> 24.718417 | CJ13: 94 | CK13: =H13*月別販売比率!$W$21 -> 23.534009 | CL13: 70 | CM13: =H13*月別販売比率!$AB$21 -> 37.077626 | CO13: =H13*月別販売比率!$AG$21 -> 30.898021 | CQ13: =H13*月別販売比率!$AL$21 -> 27.808219 | CR13: 33 | CS13: =H13*月別販売比率!$AQ$21 -> 30.898021 | CU13: =H13*月別販売比率!$AV$21 -> 18.815157 | CW13: =H13*月別販売比率!$BA$21 -> 17.186444 | CY13: =H13*月別販売比率!$BF$21 -> 24.718417
E14: +2.00 | F14: 184 | G14: =F14*4400 -> 809600 | H14: =F14*($H$6/$F$6) -> 490.10654 | I14: =H14*4400 -> 2156468.8 | J14: 0 | K14: =SUM(L14:N14) -> 33 | L14: 9 | M14: 2 | N14: 22 | P14: 45622 | Q14: 45646 | AB14: 45979 | AI14: =SUM(J14:K14)-CI14+CJ14 -> 143.79148 | AJ14: =AI14-CK14+CL14 -> 196.46167 | AK14: =AJ14-CM14+CN14 -> 137.64888 | AL14: =AK14-CO14+CP14 -> 88.638228 | AM14: =AL14-CQ14+CR14 -> 149.52864 | AN14: =AM14-CS14+CT14 -> 100.51798 | AO14: =AN14-CU14+CV14 -> 70.673253 | AP14: =AO14-CW14+CX14 -> 43.411997 | AQ14: =AP14-CY14+CZ14 -> 4.2034738 | AS14: =$H$14*月別販売比率!AG5 -> 49.010654 | AU14: =$H$14*月別販売比率!AL5 -> 44.109589 | AV14: 72 | AW14: =$H$14*月別販売比率!AQ5 -> 49.010654 | AX14: 120 | AY14: =$H$14*月別販売比率!AV5 -> 29.844732 | BA14: =$H$14*月別販売比率!BA5 -> 27.261256 | BB14: 90 | BC14: =$H$14*月別販売比率!BF5 -> 39.208524 | BE14: =$H$14*月別販売比率!C21 -> 34.731033 | BG14: =$H$14*月別販売比率!H21 -> 34.307458 | BH14: 65 | BI14: =$H$14*月別販売比率!M21 -> 49.531975 | BJ14: 55 | BK14: =$H$14*月別販売比率!R21 -> 39.208524 | BM14: =$H$14*月別販売比率!W21 -> 37.329808 | BN14: 20 | BO14: =$H$14*月別販売比率!AB21 -> 58.812785 | BP14: 50 | BQ14: =$H$14*月別販売比率!AG21 -> 49.010654 | BR14: 50 | BS14: =$H$14*月別販売比率!AL21 -> 44.109589 | BT14: 124 | BU14: =$H$14*月別販売比率!AQ21 -> 49.010654 | BV14: 105 | BW14: =$H$14*月別販売比率!AV21 -> 29.844732 | BY14: =$H$14*月別販売比率!BA21 -> 27.261256 | BZ14: 33 | CA14: =$H$14*月別販売比率!BF21 -> 39.208524 | CC14: =H14*月別販売比率!$C$21 -> 34.731033 | CE14: =H14*月別販売比率!$H$21 -> 34.307458 | CF14: 70 | CG14: =$H$14*月別販売比率!M21 -> 49.531975 | CH14: 22 | CI14: =H14*月別販売比率!$R$21 -> 39.208524 | CJ14: 150 | CK14: =H14*月別販売比率!$W$21 -> 37.329808 | CL14: 90 | CM14: =H14*月別販売比率!$AB$21 -> 58.812785 | CO14: =H14*月別販売比率!$AG$21 -> 49.010654 | CQ14: =H14*月別販売比率!$AL$21 -> 44.109589 | CR14: 105 | CS14: =H14*月別販売比率!$AQ$21 -> 49.010654 | CU14: =H14*月別販売比率!$AV$21 -> 29.844732 | CW14: =H14*月別販売比率!$BA$21 -> 27.261256 | CY14: =H14*月別販売比率!$BF$21 -> 39.208524
E15: +2.50 | F15: 54 | G15: =F15*4400 -> 237600 | H15: =F15*($H$6/$F$6) -> 143.83562 | I15: =H15*4400 -> 632876.71 | J15: 4 | K15: =SUM(L15:N15) -> 27 | L15: 8 | M15: 4 | N15: 15 | Q15: 45646 | V15: 45792 | Y15: 45884 | AC15: 46017 | AI15: =SUM(J15:K15)-CI15+CJ15 -> 49.493151 | AJ15: =AI15-CK15+CL15 -> 58.537664 | AK15: =AJ15-CM15+CN15 -> 41.27739 | AL15: =AK15-CO15+CP15 -> 26.893828 | AM15: =AL15-CQ15+CR15 -> 43.948622 | AN15: =AM15-CS15+CT15 -> 29.565061 | AO15: =AN15-CU15+CV15 -> 20.806281 | AP15: =AO15-CW15+CX15 -> 12.805695 | AQ15: =AP15-CY15+CZ15 -> 1.2988456 | AS15: =$H$15*月別販売比率!AG5 -> 14.383562 | AU15: =$H$15*月別販売比率!AL5 -> 12.945205 | AV15: 11 | AW15: =$H$15*月別販売比率!AQ5 -> 14.383562 | AX15: 30 | AY15: =$H$15*月別販売比率!AV5 -> 8.75878 | BA15: =$H$15*月別販売比率!BA5 -> 8.0005859 | BB15: 20 | BC15: =$H$15*月別販売比率!BF5 -> 11.506849 | BE15: =$H$15*月別販売比率!C21 -> 10.192803 | BG15: =$H$15*月別販売比率!H21 -> 10.068493 | BH15: 20 | BI15: =$H$15*月別販売比率!M21 -> 14.536558 | BJ15: 25 | BK15: =$H$15*月別販売比率!R21 -> 11.506849 | BM15: =$H$15*月別販売比率!W21 -> 10.955487 | BN15: 20 | BO15: =$H$15*月別販売比率!AB21 -> 17.260274 | BP15: 20 | BQ15: =$H$15*月別販売比率!AG21 -> 14.383562 | BS15: =$H$15*月別販売比率!AL21 -> 12.945205 | BT15: 39 | BU15: =$H$15*月別販売比率!AQ21 -> 14.383562 | BV15: 10 | BW15: =$H$15*月別販売比率!AV21 -> 8.75878 | BY15: =$H$15*月別販売比率!BA21 -> 8.0005859 | BZ15: 40 | CA15: =$H$15*月別販売比率!BF21 -> 11.506849 | CC15: =H15*月別販売比率!$C$21 -> 10.192803 | CE15: =H15*月別販売比率!$H$21 -> 10.068493 | CF15: 40 | CG15: =$H$15*月別販売比率!M21 -> 14.536558 | CH15: 15 | CI15: =H15*月別販売比率!$R$21 -> 11.506849 | CJ15: 30 | CK15: =H15*月別販売比率!$W$21 -> 10.955487 | CL15: 20 | CM15: =H15*月別販売比率!$AB$21 -> 17.260274 | CO15: =H15*月別販売比率!$AG$21 -> 14.383562 | CQ15: =H15*月別販売比率!$AL$21 -> 12.945205 | CR15: 30 | CS15: =H15*月別販売比率!$AQ$21 -> 14.383562 | CU15: =H15*月別販売比率!$AV$21 -> 8.75878 | CW15: =H15*月別販売比率!$BA$21 -> 8.0005859 | CY15: =H15*月別販売比率!$BF$21 -> 11.506849
E16: +3.00 | F16: 26 | G16: =F16*4400 -> 114400 | H16: =F16*($H$6/$F$6) -> 69.254186 | I16: =H16*4400 -> 304718.42 | J16: 0 | K16: =SUM(L16:N16) -> 29 | L16: 6 | M16: 14 | N16: 9 | AC16: 45662 | AI16: =SUM(J16:K16)-CI16+CJ16 -> 28.459665 | AJ16: =AI16-CK16+CL16 -> 38.184801 | AK16: =AJ16-CM16+CN16 -> 29.874299 | AL16: =AK16-CO16+CP16 -> 22.94888 | AM16: =AL16-CQ16+CR16 -> 31.716003 | AN16: =AM16-CS16+CT16 -> 24.790585 | AO16: =AN16-CU16+CV16 -> 20.573394 | AP16: =AO16-CW16+CX16 -> 16.72126 | AQ16: =AP16-CY16+CZ16 -> 11.180926 | AS16: =$H$16*月別販売比率!AG5 -> 6.9254186 | AU16: =$H$16*月別販売比率!AL5 -> 6.2328767 | AV16: 10 | AW16: =$H$16*月別販売比率!AQ5 -> 6.9254186 | AY16: =$H$16*月別販売比率!AV5 -> 4.2171904 | BA16: =$H$16*月別販売比率!BA5 -> 3.8521339 | BC16: =$H$16*月別販売比率!BF5 -> 5.5403349 | BE16: =$H$16*月別販売比率!C21 -> 4.907646 | BG16: =$H$16*月別販売比率!H21 -> 4.847793 | BH16: 5 | BI16: =$H$16*月別販売比率!M21 -> 6.9990835 | BJ16: 5 | BK16: =$H$16*月別販売比率!R21 -> 5.5403349 | BM16: =$H$16*月別販売比率!W21 -> 5.2748642 | BN16: 5 | BO16: =$H$16*月別販売比率!AB21 -> 8.3105023 | BP16: 20 | BQ16: =$H$16*月別販売比率!AG21 -> 6.9254186 | BS16: =$H$16*月別販売比率!AL21 -> 6.2328767 | BT16: 15 | BU16: =$H$16*月別販売比率!AQ21 -> 6.9254186 | BV16: 5 | BW16: =$H$16*月別販売比率!AV21 -> 4.2171904 | BY16: =$H$16*月別販売比率!BA21 -> 3.8521339 | BZ16: 5 | CA16: =$H$16*月別販売比率!BF21 -> 5.5403349 | CC16: =H16*月別販売比率!$C$21 -> 4.907646 | CE16: =H16*月別販売比率!$H$21 -> 4.847793 | CF16: 20 | CG16: =$H$16*月別販売比率!M21 -> 6.9990835 | CH16: 9 | CI16: =H16*月別販売比率!$R$21 -> 5.5403349 | CJ16: 5 | CK16: =H16*月別販売比率!$W$21 -> 5.2748642 | CL16: 15 | CM16: =H16*月別販売比率!$AB$21 -> 8.3105023 | CO16: =H16*月別販売比率!$AG$21 -> 6.9254186 | CQ16: =H16*月別販売比率!$AL$21 -> 6.2328767 | CR16: 15 | CS16: =H16*月別販売比率!$AQ$21 -> 6.9254186 | CU16: =H16*月別販売比率!$AV$21 -> 4.2171904 | CW16: =H16*月別販売比率!$BA$21 -> 3.8521339 | CY16: =H16*月別販売比率!$BF$21 -> 5.5403349
D17: 3 (廃番) | E17: +1.00 | F17: 25 | G17: =F17*4400 -> 110000 | H17: =F17*($H$6/$F$6) -> 66.590563 | I17: =H17*4400 -> 292998.48 | J17: 0 | K17: =SUM(L17:N17) -> 34 | L17: 0 | M17: 0 | N17: 34 | S17: 45707 | Y17: 45884 | AB17: 45979 | AI17: =SUM(J17:K17)-CI17+CJ17 -> 28.672755 | AJ17: =AI17-CK17+CL17 -> 23.60077 | AK17: =AJ17-CM17+CN17 -> 15.609903 | AL17: =AK17-CO17+CP17 -> 8.9508462 | AM17: =AL17-CQ17+CR17 -> 2.9576956 | AN17: =AM17-CS17+CT17 -> -3.7013608 | AO17: =AN17-CU17+CV17 -> -7.7563515 | AP17: =AO17-CW17+CX17 -> -11.460326 | AQ17: =AP17-CY17+CZ17 -> -16.787571 | AS17: =$H$17*月別販売比率!AG5 -> 6.6590563 | AU17: =$H$17*月別販売比率!AL5 -> 5.9931507 | AW17: =$H$17*月別販売比率!AQ5 -> 6.6590563 | AY17: =$H$17*月別販売比率!AV5 -> 4.0549908 | BA17: =$H$17*月別販売比率!BA5 -> 3.7039749 | BB17: 40 | BC17: =$H$17*月別販売比率!BF5 -> 5.3272451 | BE17: =$H$17*月別販売比率!C21 -> 4.7188904 | BG17: =$H$17*月別販売比率!H21 -> 4.6613394 | BI17: =$H$17*月別販売比率!M21 -> 6.729888 | BK17: =$H$17*月別販売比率!R21 -> 5.3272451 | BM17: =$H$17*月別販売比率!W21 -> 5.0719848 | BN17: 15 | BO17: =$H$17*月別販売比率!AB21 -> 7.9908676 | BP17: 15 | BQ17: =$H$17*月別販売比率!AG21 -> 6.6590563 | BS17: =$H$17*月別販売比率!AL21 -> 5.9931507 | BT17: 20 | BU17: =$H$17*月別販売比率!AQ21 -> 6.6590563 | BW17: =$H$17*月別販売比率!AV21 -> 4.0549908 | BY17: =$H$17*月別販売比率!BA21 -> 3.7039749 | CA17: =$H$17*月別販売比率!BF21 -> 5.3272451 | CC17: =H17*月別販売比率!$C$21 -> 4.7188904 | CE17: =H17*月別販売比率!$H$21 -> 4.6613394 | CG17: =$H$17*月別販売比率!M21 -> 6.729888 | CH17: 35 | CI17: =H17*月別販売比率!$R$21 -> 5.3272451 | CK17: =H17*月別販売比率!$W$21 -> 5.0719848 | CM17: =H17*月別販売比率!$AB$21 -> 7.9908676 | CO17: =H17*月別販売比率!$AG$21 -> 6.6590563 | CQ17: =H17*月別販売比率!$AL$21 -> 5.9931507 | CS17: =H17*月別販売比率!$AQ$21 -> 6.6590563 | CU17: =H17*月別販売比率!$AV$21 -> 4.0549908 | CW17: =H17*月別販売比率!$BA$21 -> 3.7039749 | CY17: =H17*月別販売比率!$BF$21 -> 5.3272451
E18: +1.50 | F18: 10 | G18: =F18*4400 -> 44000 | H18: =F18*($H$6/$F$6) -> 26.636225 | I18: =H18*4400 -> 117199.39 | J18: 0 | K18: =SUM(L18:N18) -> 15 | L18: 0 | M18: 0 | N18: 15 | S18: 45707 | V18: 45792 | Y18: 45884 | AB18: 45979 | AI18: =SUM(J18:K18)-CI18+CJ18 -> 12.869102 | AJ18: =AI18-CK18+CL18 -> 10.840308 | AK18: =AJ18-CM18+CN18 -> 7.643961 | AL18: =AK18-CO18+CP18 -> 4.9803385 | AM18: =AL18-CQ18+CR18 -> 2.5830782 | AN18: =AM18-CS18+CT18 -> -0.080544301 | AO18: =AN18-CU18+CV18 -> -1.7025406 | AP18: =AO18-CW18+CX18 -> -3.1841306 | AQ18: =AP18-CY18+CZ18 -> -5.3150286 | AS18: =$H$18*月別販売比率!AG5 -> 2.6636225 | AU18: =$H$18*月別販売比率!AL5 -> 2.3972603 | AW18: =$H$18*月別販売比率!AQ5 -> 2.6636225 | AY18: =$H$18*月別販売比率!AV5 -> 1.6219963 | BA18: =$H$18*月別販売比率!BA5 -> 1.48159 | BB18: 30 | BC18: =$H$18*月別販売比率!BF5 -> 2.130898 | BE18: =$H$18*月別販売比率!C21 -> 1.8875562 | BG18: =$H$18*月別販売比率!H21 -> 1.8645358 | BI18: =$H$18*月別販売比率!M21 -> 2.6919552 | BK18: =$H$18*月別販売比率!R21 -> 2.130898 | BM18: =$H$18*月別販売比率!W21 -> 2.0287939 | BN18: 10 | BO18: =$H$18*月別販売比率!AB21 -> 3.196347 | BP18: 15 | BQ18: =$H$18*月別販売比率!AG21 -> 2.6636225 | BS18: =$H$18*月別販売比率!AL21 -> 2.3972603 | BT18: 25 | BU18: =$H$18*月別販売比率!AQ21 -> 2.6636225 | BW18: =$H$18*月別販売比率!AV21 -> 1.6219963 | BY18: =$H$18*月別販売比率!BA21 -> 1.48159 | CA18: =$H$18*月別販売比率!BF21 -> 2.130898 | CC18: =H18*月別販売比率!$C$21 -> 1.8875562 | CE18: =H18*月別販売比率!$H$21 -> 1.8645358 | CG18: =$H$18*月別販売比率!M21 -> 2.6919552 | CH18: 15 | CI18: =H18*月別販売比率!$R$21 -> 2.130898 | CK18: =H18*月別販売比率!$W$21 -> 2.0287939 | CM18: =H18*月別販売比率!$AB$21 -> 3.196347 | CO18: =H18*月別販売比率!$AG$21 -> 2.6636225 | CQ18: =H18*月別販売比率!$AL$21 -> 2.3972603 | CS18: =H18*月別販売比率!$AQ$21 -> 2.6636225 | CU18: =H18*月別販売比率!$AV$21 -> 1.6219963 | CW18: =H18*月別販売比率!$BA$21 -> 1.48159 | CY18: =H18*月別販売比率!$BF$21 -> 2.130898
E19: +2.00 | F19: 15 | G19: =F19*4400 -> 66000 | H19: =F19*($H$6/$F$6) -> 39.954338 | I19: =H19*4400 -> 175799.09 | J19: 0 | K19: =SUM(L19:N19) -> 20 | L19: 0 | M19: 0 | N19: 20 | S19: 45707 | Y19: 45884 | AB19: 45979 | AI19: =SUM(J19:K19)-CI19+CJ19 -> 16.803653 | AJ19: =AI19-CK19+CL19 -> 13.760462 | AK19: =AJ19-CM19+CN19 -> 8.9659415 | AL19: =AK19-CO19+CP19 -> 4.9705077 | AM19: =AL19-CQ19+CR19 -> 1.3746173 | AN19: =AM19-CS19+CT19 -> -2.6208165 | AO19: =AN19-CU19+CV19 -> -5.0538109 | AP19: =AO19-CW19+CX19 -> -7.2761959 | AQ19: =AP19-CY19+CZ19 -> -10.472543 | AS19: =$H$19*月別販売比率!AG5 -> 3.9954338 | AU19: =$H$19*月別販売比率!AL5 -> 3.5958904 | AW19: =$H$19*月別販売比率!AQ5 -> 3.9954338 | AY19: =$H$19*月別販売比率!AV5 -> 2.4329945 | BA19: =$H$19*月別販売比率!BA5 -> 2.222385 | BB19: 30 | BC19: =$H$19*月別販売比率!BF5 -> 3.196347 | BE19: =$H$19*月別販売比率!C21 -> 2.8313342 | BG19: =$H$19*月別販売比率!H21 -> 2.7968037 | BI19: =$H$19*月別販売比率!M21 -> 4.0379328 | BK19: =$H$19*月別販売比率!R21 -> 3.196347 | BM19: =$H$19*月別販売比率!W21 -> 3.0431909 | BN19: 20 | BO19: =$H$19*月別販売比率!AB21 -> 4.7945205 | BP19: 10 | BQ19: =$H$19*月別販売比率!AG21 -> 3.9954338 | BS19: =$H$19*月別販売比率!AL21 -> 3.5958904 | BT19: 25 | BU19: =$H$19*月別販売比率!AQ21 -> 3.9954338 | BW19: =$H$19*月別販売比率!AV21 -> 2.4329945 | BY19: =$H$19*月別販売比率!BA21 -> 2.222385 | CA19: =$H$19*月別販売比率!BF21 -> 3.196347 | CC19: =H19*月別販売比率!$C$21 -> 2.8313342 | CE19: =H19*月別販売比率!$H$21 -> 2.7968037 | CG19: =$H$19*月別販売比率!M21 -> 4.0379328 | CH19: 20 | CI19: =H19*月別販売比率!$R$21 -> 3.196347 | CK19: =H19*月別販売比率!$W$21 -> 3.0431909 | CM19: =H19*月別販売比率!$AB$21 -> 4.7945205 | CO19: =H19*月別販売比率!$AG$21 -> 3.9954338 | CQ19: =H19*月別販売比率!$AL$21 -> 3.5958904 | CS19: =H19*月別販売比率!$AQ$21 -> 3.9954338 | CU19: =H19*月別販売比率!$AV$21 -> 2.4329945 | CW19: =H19*月別販売比率!$BA$21 -> 2.222385 | CY19: =H19*月別販売比率!$BF$21 -> 3.196347
E20: +2.50 | F20: 29 | G20: =F20*4400 -> 127600 | H20: =F20*($H$6/$F$6) -> 77.245053 | I20: =H20*4400 -> 339878.23 | J20: 0 | K20: =SUM(L20:N20) -> 33 | L20: 4 | M20: 0 | N20: 29 | S20: 45707 | AI20: =SUM(J20:K20)-CI20+CJ20 -> 26.820396 | AJ20: =AI20-CK20+CL20 -> 20.936893 | AK20: =AJ20-CM20+CN20 -> 11.667487 | AL20: =AK20-CO20+CP20 -> 3.9429816 | AM20: =AL20-CQ20+CR20 -> -3.0090731 | AN20: =AM20-CS20+CT20 -> -10.733578 | AO20: =AN20-CU20+CV20 -> -15.437368 | AP20: =AO20-CW20+CX20 -> -19.733979 | AQ20: =AP20-CY20+CZ20 -> -25.913583 | AS20: =$H$20*月別販売比率!AG5 -> 7.7245053 | AU20: =$H$20*月別販売比率!AL5 -> 6.9520548 | AW20: =$H$20*月別販売比率!AQ5 -> 7.7245053 | AY20: =$H$20*月別販売比率!AV5 -> 4.7037893 | BA20: =$H$20*月別販売比率!BA5 -> 4.2966109 | BB20: 40 | BC20: =$H$20*月別販売比率!BF5 -> 6.1796043 | BE20: =$H$20*月別販売比率!C21 -> 5.4739129 | BG20: =$H$20*月別販売比率!H21 -> 5.4071537 | BI20: =$H$20*月別販売比率!M21 -> 7.8066701 | BK20: =$H$20*月別販売比率!R21 -> 6.1796043 | BM20: =$H$20*月別販売比率!W21 -> 5.8835024 | BN20: 55 | BO20: =$H$20*月別販売比率!AB21 -> 9.2694064 | BP20: 5 | BQ20: =$H$20*月別販売比率!AG21 -> 7.7245053 | BS20: =$H$20*月別販売比率!AL21 -> 6.9520548 | BT20: 10 | BU20: =$H$20*月別販売比率!AQ21 -> 7.7245053 | BW20: =$H$20*月別販売比率!AV21 -> 4.7037893 | BY20: =$H$20*月別販売比率!BA21 -> 4.2966109 | CA20: =$H$20*月別販売比率!BF21 -> 6.1796043 | CC20: =H20*月別販売比率!$C$21 -> 5.4739129 | CE20: =H20*月別販売比率!$H$21 -> 5.4071537 | CG20: =$H$20*月別販売比率!M21 -> 7.8066701 | CH20: 30 | CI20: =H20*月別販売比率!$R$21 -> 6.1796043 | CK20: =H20*月別販売比率!$W$21 -> 5.8835024 | CM20: =H20*月別販売比率!$AB$21 -> 9.2694064 | CO20: =H20*月別販売比率!$AG$21 -> 7.7245053 | CQ20: =H20*月別販売比率!$AL$21 -> 6.9520548 | CS20: =H20*月別販売比率!$AQ$21 -> 7.7245053 | CU20: =H20*月別販売比率!$AV$21 -> 4.7037893 | CW20: =H20*月別販売比率!$BA$21 -> 4.2966109 | CY20: =H20*月別販売比率!$BF$21 -> 6.1796043
E21: +3.00 | F21: 18 | G21: =F21*4400 -> 79200 | H21: =F21*($H$6/$F$6) -> 47.945205 | I21: =H21*4400 -> 210958.9 | J21: 0 | K21: =SUM(L21:N21) -> 13 | L21: 4 | M21: 0 | N21: 9 | S21: 45707 | Y21: 45884 | AI21: =SUM(J21:K21)-CI21+CJ21 -> 9.1643836 | AJ21: =AI21-CK21+CL21 -> 5.5125545 | AK21: =AJ21-CM21+CN21 -> -0.24087015 | AL21: =AK21-CO21+CP21 -> -5.0353907 | AM21: =AL21-CQ21+CR21 -> -9.3504592 | AN21: =AM21-CS21+CT21 -> -14.14498 | AO21: =AN21-CU21+CV21 -> -17.064573 | AP21: =AO21-CW21+CX21 -> -19.731435 | AQ21: =AP21-CY21+CZ21 -> -23.567051 | AS21: =$H$21*月別販売比率!AG5 -> 4.7945205 | AU21: =$H$21*月別販売比率!AL5 -> 4.3150685 | AW21: =$H$21*月別販売比率!AQ5 -> 4.7945205 | AY21: =$H$21*月別販売比率!AV5 -> 2.9195933 | BA21: =$H$21*月別販売比率!BA5 -> 2.666862 | BB21: 15 | BC21: =$H$21*月別販売比率!BF5 -> 3.8356164 | BE21: =$H$21*月別販売比率!C21 -> 3.3976011 | BG21: =$H$21*月別販売比率!H21 -> 3.3561644 | BI21: =$H$21*月別販売比率!M21 -> 4.8455193 | BK21: =$H$21*月別販売比率!R21 -> 3.8356164 | BM21: =$H$21*月別販売比率!W21 -> 3.6518291 | BN21: 35 | BO21: =$H$21*月別販売比率!AB21 -> 5.7534247 | BQ21: =$H$21*月別販売比率!AG21 -> 4.7945205 | BS21: =$H$21*月別販売比率!AL21 -> 4.3150685 | BT21: 10 | BU21: =$H$21*月別販売比率!AQ21 -> 4.7945205 | BW21: =$H$21*月別販売比率!AV21 -> 2.9195933 | BY21: =$H$21*月別販売比率!BA21 -> 2.666862 | CA21: =$H$21*月別販売比率!BF21 -> 3.8356164 | CC21: =H21*月別販売比率!$C$21 -> 3.3976011 | CE21: =H21*月別販売比率!$H$21 -> 3.3561644 | CG21: =$H$21*月別販売比率!M21 -> 4.8455193 | CH21: 15 | CI21: =H21*月別販売比率!$R$21 -> 3.8356164 | CK21: =H21*月別販売比率!$W$21 -> 3.6518291 | CM21: =H21*月別販売比率!$AB$21 -> 5.7534247 | CO21: =H21*月別販売比率!$AG$21 -> 4.7945205 | CQ21: =H21*月別販売比率!$AL$21 -> 4.3150685 | CS21: =H21*月別販売比率!$AQ$21 -> 4.7945205 | CU21: =H21*月別販売比率!$AV$21 -> 2.9195933 | CW21: =H21*月別販売比率!$BA$21 -> 2.666862 | CY21: =H21*月別販売比率!$BF$21 -> 3.8356164
D22: 4 | E22: +1.00 | F22: 100 | G22: =F22*4400 -> 440000 | H22: =F22*($H$6/$F$6) -> 266.36225 | I22: =H22*4400 -> 1171993.9 | J22: 2 | K22: =SUM(L22:N22) -> 75 | L22: 10 | M22: 0 | N22: 65 | AI22: =SUM(J22:K22)-CI22+CJ22 -> 105.69102 | AJ22: =AI22-CK22+CL22 -> 135.40308 | AK22: =AJ22-CM22+CN22 -> 103.43961 | AL22: =AK22-CO22+CP22 -> 76.803385 | AM22: =AL22-CQ22+CR22 -> 87.830782 | AN22: =AM22-CS22+CT22 -> 61.194557 | AO22: =AN22-CU22+CV22 -> 44.974594 | AP22: =AO22-CW22+CX22 -> 30.158694 | AQ22: =AP22-CY22+CZ22 -> 8.849714 | AS22: =$H$22*月別販売比率!AG5 -> 26.636225 | AU22: =$H$22*月別販売比率!AL5 -> 23.972603 | AV22: 40 | AW22: =$H$22*月別販売比率!AQ5 -> 26.636225 | AX22: 50 | AY22: =$H$22*月別販売比率!AV5 -> 16.219963 | BA22: =$H$22*月別販売比率!BA5 -> 14.8159 | BC22: =$H$22*月別販売比率!BF5 -> 21.30898 | BD22: 45 | BE22: =$H$22*月別販売比率!C21 -> 18.875562 | BG22: =$H$22*月別販売比率!H21 -> 18.645358 | BH22: 40 | BI22: =$H$22*月別販売比率!M21 -> 26.919552 | BJ22: 35 | BK22: =$H$22*月別販売比率!R21 -> 21.30898 | BM22: =$H$22*月別販売比率!W21 -> 20.287939 | BN22: 40 | BO22: =$H$22*月別販売比率!AB21 -> 31.96347 | BQ22: =$H$22*月別販売比率!AG21 -> 26.636225 | BR22: 15 | BS22: =$H$22*月別販売比率!AL21 -> 23.972603 | BT22: 75 | BU22: =$H$22*月別販売比率!AQ21 -> 26.636225 | BV22: 30 | BW22: =$H$22*月別販売比率!AV21 -> 16.219963 | BY22: =$H$22*月別販売比率!BA21 -> 14.8159 | CA22: =$H$22*月別販売比率!BF21 -> 21.30898 | CC22: =H22*月別販売比率!$C$21 -> 18.875562 | CE22: =H22*月別販売比率!$H$21 -> 18.645358 | CF22: 30 | CG22: =$H$22*月別販売比率!M21 -> 26.919552 | CH22: 65 | CI22: =H22*月別販売比率!$R$21 -> 21.30898 | CJ22: 50 | CK22: =H22*月別販売比率!$W$21 -> 20.287939 | CL22: 50 | CM22: =H22*月別販売比率!$AB$21 -> 31.96347 | CO22: =H22*月別販売比率!$AG$21 -> 26.636225 | CQ22: =H22*月別販売比率!$AL$21 -> 23.972603 | CR22: 35 | CS22: =H22*月別販売比率!$AQ$21 -> 26.636225 | CU22: =H22*月別販売比率!$AV$21 -> 16.219963 | CW22: =H22*月別販売比率!$BA$21 -> 14.8159 | CY22: =H22*月別販売比率!$BF$21 -> 21.30898
E23: +1.50 | F23: 133 | G23: =F23*4400 -> 585200 | H23: =F23*($H$6/$F$6) -> 354.2618 | I23: =H23*4400 -> 1558751.9 | J23: 19 | K23: =SUM(L23:N23) -> 129 | L23: 10 | M23: 10 | N23: 109 | P23: 45622 | Q23: 45646 | AI23: =SUM(J23:K23)-CI23+CJ23 -> 134.65906 | AJ23: =AI23-CK23+CL23 -> 167.6761 | AK23: =AJ23-CM23+CN23 -> 125.16468 | AL23: =AK23-CO23+CP23 -> 89.738502 | AM23: =AL23-CQ23+CR23 -> 142.85494 | AN23: =AM23-CS23+CT23 -> 107.42876 | AO23: =AN23-CU23+CV23 -> 85.85621 | AP23: =AO23-CW23+CX23 -> 66.151063 | AQ23: =AP23-CY23+CZ23 -> 37.81012 | AS23: =$H$23*月別販売比率!AG5 -> 35.42618 | AU23: =$H$23*月別販売比率!AL5 -> 31.883562 | AV23: 50 | AW23: =$H$23*月別販売比率!AQ5 -> 35.42618 | AX23: 65 | AY23: =$H$23*月別販売比率!AV5 -> 21.572551 | BA23: =$H$23*月別販売比率!BA5 -> 19.705147 | BC23: =$H$23*月別販売比率!BF5 -> 28.340944 | BD23: 70 | BE23: =$H$23*月別販売比率!C21 -> 25.104497 | BG23: =$H$23*月別販売比率!H21 -> 24.798326 | BH23: 55 | BI23: =$H$23*月別販売比率!M21 -> 35.803004 | BJ23: 50 | BK23: =$H$23*月別販売比率!R21 -> 28.340944 | BM23: =$H$23*月別販売比率!W21 -> 26.982959 | BN23: 70 | BO23: =$H$23*月別販売比率!AB21 -> 42.511416 | BQ23: =$H$23*月別販売比率!AG21 -> 35.42618 | BR23: 10 | BS23: =$H$23*月別販売比率!AL21 -> 31.883562 | BT23: 54 | BU23: =$H$23*月別販売比率!AQ21 -> 35.42618 | BV23: 20 | BW23: =$H$23*月別販売比率!AV21 -> 21.572551 | BY23: =$H$23*月別販売比率!BA21 -> 19.705147 | BZ23: 40 | CA23: =$H$23*月別販売比率!BF21 -> 28.340944 | CC23: =H23*月別販売比率!$C$21 -> 25.104497 | CE23: =H23*月別販売比率!$H$21 -> 24.798326 | CF23: 120 | CG23: =$H$23*月別販売比率!M21 -> 35.803004 | CH23: 59 | CI23: =H23*月別販売比率!$R$21 -> 28.340944 | CJ23: 15 | CK23: =H23*月別販売比率!$W$21 -> 26.982959 | CL23: 60 | CM23: =H23*月別販売比率!$AB$21 -> 42.511416 | CO23: =H23*月別販売比率!$AG$21 -> 35.42618 | CQ23: =H23*月別販売比率!$AL$21 -> 31.883562 | CR23: 85 | CS23: =H23*月別販売比率!$AQ$21 -> 35.42618 | CU23: =H23*月別販売比率!$AV$21 -> 21.572551 | CW23: =H23*月別販売比率!$BA$21 -> 19.705147 | CY23: =H23*月別販売比率!$BF$21 -> 28.340944
E24: +2.00 | F24: 62 | G24: =F24*4400 -> 272800 | H24: =F24*($H$6/$F$6) -> 165.1446 | I24: =H24*4400 -> 726636.23 | J24: 5 | K24: =SUM(L24:N24) -> 38 | L24: 9 | M24: 0 | N24: 29 | P24: 45622 | U24: 45752 | AC24: 46017 | AI24: =SUM(J24:K24)-CI24+CJ24 -> 59.788432 | AJ24: =AI24-CK24+CL24 -> 72.20991 | AK24: =AJ24-CM24+CN24 -> 52.392558 | AL24: =AK24-CO24+CP24 -> 35.878099 | AM24: =AL24-CQ24+CR24 -> 61.015085 | AN24: =AM24-CS24+CT24 -> 44.500625 | AO24: =AN24-CU24+CV24 -> 34.444248 | AP24: =AO24-CW24+CX24 -> 25.25839 | AQ24: =AP24-CY24+CZ24 -> 12.046823 | AS24: =$H$24*月別販売比率!AG5 -> 16.51446 | AU24: =$H$24*月別販売比率!AL5 -> 14.863014 | AV24: 30 | AW24: =$H$24*月別販売比率!AQ5 -> 16.51446 | AX24: 50 | AY24: =$H$24*月別販売比率!AV5 -> 10.056377 | BA24: =$H$24*月別販売比率!BA5 -> 9.1858578 | BC24: =$H$24*月別販売比率!BF5 -> 13.211568 | BD24: 25 | BE24: =$H$24*月別販売比率!C21 -> 11.702848 | BG24: =$H$24*月別販売比率!H21 -> 11.560122 | BH24: 20 | BI24: =$H$24*月別販売比率!M21 -> 16.690122 | BJ24: 12 | BK24: =$H$24*月別販売比率!R21 -> 13.211568 | BM24: =$H$24*月別販売比率!W21 -> 12.578522 | BN24: 40 | BO24: =$H$24*月別販売比率!AB21 -> 19.817352 | BQ24: =$H$24*月別販売比率!AG21 -> 16.51446 | BR24: 10 | BS24: =$H$24*月別販売比率!AL21 -> 14.863014 | BT24: 34 | BU24: =$H$24*月別販売比率!AQ21 -> 16.51446 | BV24: 15 | BW24: =$H$24*月別販売比率!AV21 -> 10.056377 | BY24: =$H$24*月別販売比率!BA21 -> 9.1858578 | BZ24: 25 | CA24: =$H$24*月別販売比率!BF21 -> 13.211568 | CC24: =H24*月別販売比率!$C$21 -> 11.702848 | CE24: =H24*月別販売比率!$H$21 -> 11.560122 | CF24: 30 | CG24: =$H$24*月別販売比率!M21 -> 16.690122 | CH24: 29 | CI24: =H24*月別販売比率!$R$21 -> 13.211568 | CJ24: 30 | CK24: =H24*月別販売比率!$W$21 -> 12.578522 | CL24: 25 | CM24: =H24*月別販売比率!$AB$21 -> 19.817352 | CO24: =H24*月別販売比率!$AG$21 -> 16.51446 | CQ24: =H24*月別販売比率!$AL$21 -> 14.863014 | CR24: 40 | CS24: =H24*月別販売比率!$AQ$21 -> 16.51446 | CU24: =H24*月別販売比率!$AV$21 -> 10.056377 | CW24: =H24*月別販売比率!$BA$21 -> 9.1858578 | CY24: =H24*月別販売比率!$BF$21 -> 13.211568
E25: +2.50 | F25: 31 | G25: =F25*4400 -> 136400 | H25: =F25*($H$6/$F$6) -> 82.572298 | I25: =H25*4400 -> 363318.11 | J25: 5 | K25: =SUM(L25:N25) -> 9 | L25: 9 | M25: 0 | P25: 45622 | Q25: 45646 | Y25: 45884 | AB25: 45979 | AC25: 45662 | AI25: =SUM(J25:K25)-CI25+CJ25 -> 24.394216 | AJ25: =AI25-CK25+CL25 -> 28.104955 | AK25: =AJ25-CM25+CN25 -> 18.196279 | AL25: =AK25-CO25+CP25 -> 9.9390493 | AM25: =AL25-CQ25+CR25 -> 27.507542 | AN25: =AM25-CS25+CT25 -> 19.250313 | AO25: =AN25-CU25+CV25 -> 14.222124 | AP25: =AO25-CW25+CX25 -> 9.6291952 | AQ25: =AP25-CY25+CZ25 -> 3.0234113 | AS25: =$H$25*月別販売比率!AG5 -> 8.2572298 | AU25: =$H$25*月別販売比率!AL5 -> 7.4315068 | AV25: 12 | AW25: =$H$25*月別販売比率!AQ5 -> 8.2572298 | AX25: 50 | AY25: =$H$25*月別販売比率!AV5 -> 5.0281885 | BA25: =$H$25*月別販売比率!BA5 -> 4.5929289 | BC25: =$H$25*月別販売比率!BF5 -> 6.6057839 | BE25: =$H$25*月別販売比率!C21 -> 5.8514241 | BG25: =$H$25*月別販売比率!H21 -> 5.7800609 | BH25: 10 | BI25: =$H$25*月別販売比率!M21 -> 8.3450611 | BJ25: 4 | BK25: =$H$25*月別販売比率!R21 -> 6.6057839 | BM25: =$H$25*月別販売比率!W21 -> 6.2892612 | BN25: 25 | BO25: =$H$25*月別販売比率!AB21 -> 9.9086758 | BQ25: =$H$25*月別販売比率!AG21 -> 8.2572298 | BR25: 5 | BS25: =$H$25*月別販売比率!AL21 -> 7.4315068 | BT25: 20 | BU25: =$H$25*月別販売比率!AQ21 -> 8.2572298 | BW25: =$H$25*月別販売比率!AV21 -> 5.0281885 | BY25: =$H$25*月別販売比率!BA21 -> 4.5929289 | BZ25: 33 | CA25: =$H$25*月別販売比率!BF21 -> 6.6057839 | CC25: =H25*月別販売比率!$C$21 -> 5.8514241 | CE25: =H25*月別販売比率!$H$21 -> 5.7800609 | CF25: 20 | CG25: =$H$25*月別販売比率!M21 -> 8.3450611 | CH25: 0 | CI25: =H25*月別販売比率!$R$21 -> 6.6057839 | CJ25: 17 | CK25: =H25*月別販売比率!$W$21 -> 6.2892612 | CL25: 10 | CM25: =H25*月別販売比率!$AB$21 -> 9.9086758 | CO25: =H25*月別販売比率!$AG$21 -> 8.2572298 | CQ25: =H25*月別販売比率!$AL$21 -> 7.4315068 | CR25: 25 | CS25: =H25*月別販売比率!$AQ$21 -> 8.2572298 | CU25: =H25*月別販売比率!$AV$21 -> 5.0281885 | CW25: =H25*月別販売比率!$BA$21 -> 4.5929289 | CY25: =H25*月別販売比率!$BF$21 -> 6.6057839
E26: +3.00 | F26: 32 | G26: =F26*4400 -> 140800 | H26: =F26*($H$6/$F$6) -> 85.235921 | I26: =H26*4400 -> 375038.05 | J26: 0 | K26: =SUM(L26:N26) -> 27 | L26: 8 | M26: 5 | N26: 14 | AI26: =SUM(J26:K26)-CI26+CJ26 -> 35.181126 | AJ26: =AI26-CK26+CL26 -> 38.688986 | AK26: =AJ26-CM26+CN26 -> 28.460675 | AL26: =AK26-CO26+CP26 -> 19.937083 | AM26: =AL26-CQ26+CR26 -> 32.26585 | AN26: =AM26-CS26+CT26 -> 23.742258 | AO26: =AN26-CU26+CV26 -> 18.55187 | AP26: =AO26-CW26+CX26 -> 13.810782 | AQ26: =AP26-CY26+CZ26 -> 6.9919085 | AS26: =$H$26*月別販売比率!AG5 -> 8.5235921 | AU26: =$H$26*月別販売比率!AL5 -> 7.6712329 | AW26: =$H$26*月別販売比率!AQ5 -> 8.5235921 | AX26: 20 | AY26: =$H$26*月別販売比率!AV5 -> 5.1903882 | BA26: =$H$26*月別販売比率!BA5 -> 4.7410879 | BC26: =$H$26*月別販売比率!BF5 -> 6.8188737 | BE26: =$H$26*月別販売比率!C21 -> 6.0401797 | BG26: =$H$26*月別販売比率!H21 -> 5.9665145 | BH26: 10 | BI26: =$H$26*月別販売比率!M21 -> 8.6142566 | BJ26: 5 | BK26: =$H$26*月別販売比率!R21 -> 6.8188737 | BM26: =$H$26*月別販売比率!W21 -> 6.4921405 | BN26: 10 | BO26: =$H$26*月別販売比率!AB21 -> 10.228311 | BQ26: =$H$26*月別販売比率!AG21 -> 8.5235921 | BR26: 10 | BS26: =$H$26*月別販売比率!AL21 -> 7.6712329 | BT26: 5 | BU26: =$H$26*月別販売比率!AQ21 -> 8.5235921 | BW26: =$H$26*月別販売比率!AV21 -> 5.1903882 | BY26: =$H$26*月別販売比率!BA21 -> 4.7410879 | BZ26: 20 | CA26: =$H$26*月別販売比率!BF21 -> 6.8188737 | CC26: =H26*月別販売比率!$C$21 -> 6.0401797 | CE26: =H26*月別販売比率!$H$21 -> 5.9665145 | CF26: 20 | CG26: =$H$26*月別販売比率!M21 -> 8.6142566 | CH26: 14 | CI26: =H26*月別販売比率!$R$21 -> 6.8188737 | CJ26: 15 | CK26: =H26*月別販売比率!$W$21 -> 6.4921405 | CL26: 10 | CM26: =H26*月別販売比率!$AB$21 -> 10.228311 | CO26: =H26*月別販売比率!$AG$21 -> 8.5235921 | CQ26: =H26*月別販売比率!$AL$21 -> 7.6712329 | CR26: 20 | CS26: =H26*月別販売比率!$AQ$21 -> 8.5235921 | CU26: =H26*月別販売比率!$AV$21 -> 5.1903882 | CW26: =H26*月別販売比率!$BA$21 -> 4.7410879 | CY26: =H26*月別販売比率!$BF$21 -> 6.8188737
B27: 2 | C27: flc-002 | F27: =SUM(F28:F37) -> 453 | G27: =SUM(G28:G37) -> 1644390 | H27: 2323 | I27: =SUM(I28:I37) -> 9625790.4 | J27: =SUM(J28:J37) -> 559 | K27: =SUM(K28:K37) -> 224 | L27: =SUM(L28:L37) -> 58 | M27: =SUM(M28:M37) -> 166 | N27: =SUM(N28:N37) -> 0 | AS27: =SUM(AS28:AS37) -> 265.17329 | AT27: =SUM(AT28:AT37) -> 0 | AU27: =SUM(AU28:AU37) -> 238.65596 | AV27: =SUM(AV28:AV37) -> 0 | AW27: =SUM(AW28:AW37) -> 265.17329 | AX27: =SUM(AX28:AX37) -> 300 | AY27: =SUM(AY28:AY37) -> 161.47562 | AZ27: =SUM(AZ28:AZ37) -> 300 | ... BE27: =SUM(BE28:BE37) -> 187.91307 | BG27: =SUM(BG28:BG37) -> 185.6213 | BH27: =SUM(BH28:BH37) -> 0 | BI27: =SUM(BI28:BI37) -> 267.99391 | BJ27: =SUM(BJ28:BJ37) -> 300 | BK27: =SUM(BK28:BK37) -> 212.13863 | BL27: =SUM(BL28:BL37) -> 600 | BM27: =SUM(BM28:BM37) -> 201.9738 | BN27: =SUM(BN28:BN37) -> 0 | ... CT27: =SUM(CT28:CT37) -> 345 | CU27: 161.47562 | CV27: =SUM(CV28:CV37) -> 0 | CW27: =SUM(CW28:CW37) -> 147.49766 | CX27: =SUM(CX28:CX37) -> 0 | CY27: =SUM(CY28:CY37) -> 212.13863 | CZ27: =SUM(CZ28:CZ37) -> 0
C28: 入荷：5月 568枚 8月 330枚 10月 280枚 11月 300枚 11月 900枚（累進) 12月 300枚 | D28: 1 | E28: +1.00 | F28: 31 | G28: =F28*3630 -> 112530 | H28: 200 | I28: =H28*3630 -> 726000 | J28: 0 | K28: =SUM(L28:N28) -> 10 | L28: 0 | M28: 10 | S28: 45693 | X28: 45869 | AD28: 46045 | AI28: =SUM(J28:K28)-CI28+CJ28 -> -6 | AJ28: =0-CK28+CL28 -> 14.766656 | AK28: =AJ28-CM28+CN28 -> -9.2333441 | AL28: =0-CO28+CP28 -> 20 | AM28: =AL28-CQ28+CR28 -> 37 | AN28: =AM28-CS28+CT28 -> 42 | AO28: =AN28-CU28+CV28 -> 29.821125 | AP28: =AO28-CW28+CX28 -> 18.696501 | AQ28: =AP28-CY28+CZ28 -> 2.6965008 | AS28: =$H$28*月別販売比率!AG5 -> 20 | AU28: =$H$28*月別販売比率!AL5 -> 18 | AW28: =$H$28*月別販売比率!AQ5 -> 20 | AX28: 20 | AY28: =$H$28*月別販売比率!AV5 -> 12.178875 | AZ28: 42 | BA28: =$H$28*月別販売比率!BA5 -> 11.124624 | BB28: 42 | BC28: =$H$28*月別販売比率!BF5 -> 16 | BE28: =$H$28*月別販売比率!C21 -> 14.17285 | BG28: =$H$28*月別販売比率!H21 -> 14 | BI28: =$H$28*月別販売比率!M21 -> 20.212738 | BK28: =$H$28*月別販売比率!R21 -> 16 | BL28: 60 | BM28: =$H$28*月別販売比率!W21 -> 15.233344 | BO28: =$H$28*月別販売比率!AB21 -> 24 | BP28: 35 | BQ28: =$H$28*月別販売比率!AG21 -> 20 | BS28: =$H$28*月別販売比率!AL21 -> 18 | BT28: 20 | BU28: =$H$28*月別販売比率!AQ21 -> 20 | BW28: =$H$28*月別販売比率!AV21 -> 12.178875 | BX28: 37 | BY28: =$H$28*月別販売比率!BA21 -> 11.124624 | CA28: =$H$28*月別販売比率!BF21 -> 16 | CC28: =H28*月別販売比率!$C$21 -> 14.17285 | CE28: =H28*月別販売比率!$H$21 -> 14 | CF28: 62 | CG28: =H28*月別販売比率!$M$21 -> 20.212738 | CI28: =H28*月別販売比率!$R$21 -> 16 | CK28: =H28*月別販売比率!$W$21 -> 15.233344 | CL28: 30 | CM28: =H28*月別販売比率!$AB$21 -> 24 | CO28: =H28*月別販売比率!$AG$21 -> 20 | CP28: 40 | CQ28: =H28*月別販売比率!$AL$21 -> 18 | CR28: 35 | CS28: =H28*月別販売比率!$AQ$21 -> 20 | CT28: 25 | CU28: =H28*月別販売比率!$AV$21 -> 12.178875 | CW28: =H28*月別販売比率!$BA$21 -> 11.124624 | CY28: =H28*月別販売比率!$BF$21 -> 16
E29: +1.50 | F29: 32 | G29: =F29*3630 -> 116160 | H29: 320 | I29: =H29*3630 -> 1161600 | J29: 24 | K29: =SUM(L29:N29) -> 21 | L29: 9 | M29: 12 | S29: 45693 | X29: 45869 | AD29: 46045 | AI29: =SUM(J29:K29)-CI29+CJ29 -> 19.4 | AJ29: =AI29-CK29+CL29 -> 55.026649 | AK29: =AJ29-CM29+CN29 -> 16.626649 | AL29: =AK29-CO29+CP29 -> 44.626649 | AM29: =AL29-CQ29+CR29 -> 45.826649 | AN29: =AM29-CS29+CT29 -> 58.826649 | AO29: =AN29-CU29+CV29 -> 39.340449 | AP29: =AO29-CW29+CX29 -> 21.541051 | AQ29: =AP29-CY29+CZ29 -> -4.0589493 | AS29: =$H$29*月別販売比率!AG5 -> 32 | AU29: =$H$29*月別販売比率!AL5 -> 28.8 | AW29: =$H$29*月別販売比率!AQ5 -> 32 | AX29: 30 | AY29: =$H$29*月別販売比率!AV5 -> 19.4862 | AZ29: 48 | BA29: =$H$29*月別販売比率!BA5 -> 17.799399 | BB29: 48 | BC29: =$H$29*月別販売比率!BF5 -> 25.6 | BE29: =$H$29*月別販売比率!C21 -> 22.67656 | BG29: =$H$29*月別販売比率!H21 -> 22.4 | BI29: =$H$29*月別販売比率!M21 -> 32.340381 | BK29: =$H$29*月別販売比率!R21 -> 25.6 | BL29: 60 | BM29: =$H$29*月別販売比率!W21 -> 24.373351 | BO29: =$H$29*月別販売比率!AB21 -> 38.4 | BP29: 40 | BQ29: =$H$29*月別販売比率!AG21 -> 32 | BS29: =$H$29*月別販売比率!AL21 -> 28.8 | BT29: 25 | BU29: =$H$29*月別販売比率!AQ21 -> 32 | BW29: =$H$29*月別販売比率!AV21 -> 19.4862 | BX29: 40 | BY29: =$H$29*月別販売比率!BA21 -> 17.799399 | CA29: =$H$29*月別販売比率!BF21 -> 25.6 | CC29: =H29*月別販売比率!$C$21 -> 22.67656 | CE29: =H29*月別販売比率!$H$21 -> 22.4 | CF29: 96 | CG29: =H29*月別販売比率!$M$21 -> 32.340381 | CI29: =H29*月別販売比率!$R$21 -> 25.6 | CK29: =H29*月別販売比率!$W$21 -> 24.373351 | CL29: 60 | CM29: =H29*月別販売比率!$AB$21 -> 38.4 | CO29: =H29*月別販売比率!$AG$21 -> 32 | CP29: 60 | CQ29: =H29*月別販売比率!$AL$21 -> 28.8 | CR29: 30 | CS29: =H29*月別販売比率!$AQ$21 -> 32 | CT29: 45 | CU29: =H29*月別販売比率!$AV$21 -> 19.4862 | CW29: =H29*月別販売比率!$BA$21 -> 17.799399 | CY29: =H29*月別販売比率!$BF$21 -> 25.6
E30: +2.00 | F30: 25 | G30: =F30*3630 -> 90750 | H30: 260 | I30: =H30*3630 -> 943800 | J30: 34 | K30: =SUM(L30:N30) -> 22 | L30: 10 | M30: 12 | S30: 45693 | X30: 45869 | AD30: 46045 | AI30: =SUM(J30:K30)-CI30+CJ30 -> 35.2 | AJ30: =AI30-CK30+CL30 -> 65.396653 | AK30: =AJ30-CM30+CN30 -> 34.196653 | AL30: =AK30-CO30+CP30 -> 48.196653 | AM30: =AL30-CQ30+CR30 -> 54.796653 | AN30: =AM30-CS30+CT30 -> 63.796653 | AO30: =AN30-CU30+CV30 -> 47.964115 | AP30: =AO30-CW30+CX30 -> 33.502104 | AQ30: =AP30-CY30+CZ30 -> 12.702104 | AS30: =$H$30*月別販売比率!AG5 -> 26 | AU30: =$H$30*月別販売比率!AL5 -> 23.4 | AW30: =$H$30*月別販売比率!AQ5 -> 26 | AX30: 30 | AY30: =$H$30*月別販売比率!AV5 -> 15.832538 | AZ30: 36 | BA30: =$H$30*月別販売比率!BA5 -> 14.462011 | BB30: 36 | BC30: =$H$30*月別販売比率!BF5 -> 20.8 | BE30: =$H$30*月別販売比率!C21 -> 18.424705 | BG30: =$H$30*月別販売比率!H21 -> 18.2 | BI30: =$H$30*月別販売比率!M21 -> 26.276559 | BK30: =$H$30*月別販売比率!R21 -> 20.8 | BL30: 35 | BM30: =$H$30*月別販売比率!W21 -> 19.803347 | BO30: =$H$30*月別販売比率!AB21 -> 31.2 | BP30: 35 | BQ30: =$H$30*月別販売比率!AG21 -> 26 | BS30: =$H$30*月別販売比率!AL21 -> 23.4 | BT30: 0 | BU30: =$H$30*月別販売比率!AQ21 -> 26 | BW30: =$H$30*月別販売比率!AV21 -> 15.832538 | BX30: 42 | BY30: =$H$30*月別販売比率!BA21 -> 14.462011 | CA30: =$H$30*月別販売比率!BF21 -> 20.8 | CC30: =H30*月別販売比率!$C$21 -> 18.424705 | CE30: =H30*月別販売比率!$H$21 -> 18.2 | CF30: 81 | CG30: =H30*月別販売比率!$M$21 -> 26.276559 | CI30: =H30*月別販売比率!$R$21 -> 20.8 | CK30: =H30*月別販売比率!$W$21 -> 19.803347 | CL30: 50 | CM30: =H30*月別販売比率!$AB$21 -> 31.2 | CO30: =H30*月別販売比率!$AG$21 -> 26 | CP30: 40 | CQ30: =H30*月別販売比率!$AL$21 -> 23.4 | CR30: 30 | CS30: =H30*月別販売比率!$AQ$21 -> 26 | CT30: 35 | CU30: =H30*月別販売比率!$AV$21 -> 15.832538 | CW30: =H30*月別販売比率!$BA$21 -> 14.462011 | CY30: =H30*月別販売比率!$BF$21 -> 20.8
E31: +2.50 | F31: 28 | G31: =F31*3630 -> 101640 | H31: =F31*($H$27/$F$27) -> 143.58499 | I31: =H31*3630 -> 521213.51 | J31: 7 | K31: =SUM(L31:N31) -> 27 | L31: 7 | M31: 20 | Q31: 45631 | AI31: =SUM(J31:K31)-CI31+CJ31 -> 22.513201 | AJ31: =AI31-CK31+CL31 -> 31.576803 | AK31: =AJ31-CM31+CN31 -> 14.346605 | AL31: =AK31-CO31+CP31 -> 19.988106 | AM31: =AL31-CQ31+CR31 -> 32.065457 | AN31: =AM31-CS31+CT31 -> 42.706958 | AO31: =AN31-CU31+CV31 -> 33.963439 | AP31: =AO31-CW31+CX31 -> 25.976794 | AQ31: =AP31-CY31+CZ31 -> 14.489995 | AS31: =$H$31*月別販売比率!AG5 -> 14.358499 | AU31: =$H$31*月別販売比率!AL5 -> 12.922649 | AW31: =$H$31*月別販売比率!AQ5 -> 14.358499 | AX31: 25 | AY31: =$H$31*月別販売比率!AV5 -> 8.7435182 | AZ31: 12 | BA31: =$H$31*月別販売比率!BA5 -> 7.9866452 | BB31: 12 | BC31: =$H$31*月別販売比率!BF5 -> 11.486799 | BE31: =$H$31*月別販売比率!C21 -> 10.175043 | BF31: 48 | BG31: =$H$31*月別販売比率!H21 -> 10.050949 | BI31: =$H$31*月別販売比率!M21 -> 14.511229 | BK31: =$H$31*月別販売比率!R21 -> 11.486799 | BL31: 25 | BM31: =$H$31*月別販売比率!W21 -> 10.936398 | BO31: =$H$31*月別販売比率!AB21 -> 17.230199 | BP31: 40 | BQ31: =$H$31*月別販売比率!AG21 -> 14.358499 | BS31: =$H$31*月別販売比率!AL21 -> 12.922649 | BT31: 0 | BU31: =$H$31*月別販売比率!AQ21 -> 14.358499 | BW31: =$H$31*月別販売比率!AV21 -> 8.7435182 | BX31: 35 | BY31: =$H$31*月別販売比率!BA21 -> 7.9866452 | CA31: =$H$31*月別販売比率!BF21 -> 11.486799 | CC31: =H31*月別販売比率!$C$21 -> 10.175043 | CE31: =H31*月別販売比率!$H$21 -> 10.050949 | CF31: 32 | CG31: =H31*月別販売比率!$M$21 -> 14.511229 | CI31: =H31*月別販売比率!$R$21 -> 11.486799 | CK31: =H31*月別販売比率!$W$21 -> 10.936398 | CL31: 20 | CM31: =H31*月別販売比率!$AB$21 -> 17.230199 | CO31: =H31*月別販売比率!$AG$21 -> 14.358499 | CP31: 20 | CQ31: =H31*月別販売比率!$AL$21 -> 12.922649 | CR31: 25 | CS31: =H31*月別販売比率!$AQ$21 -> 14.358499 | CT31: 25 | CU31: =H31*月別販売比率!$AV$21 -> 8.7435182 | CW31: =H31*月別販売比率!$BA$21 -> 7.9866452 | CY31: =H31*月別販売比率!$BF$21 -> 11.486799
E32: +3.00 | F32: 17 | G32: =F32*3630 -> 61710 | H32: =F32*($H$27/$F$27) -> 87.1766 | I32: =H32*3630 -> 316451.06 | J32: 4 | K32: =SUM(L32:N32) -> 21 | L32: 3 | M32: 18 | Q32: 45631 | R32: 45685 | AD32: 46045 | AI32: =SUM(J32:K32)-CI32+CJ32 -> 18.025872 | AJ32: =AI32-CK32+CL32 -> 31.385916 | AK32: =AJ32-CM32+CN32 -> 20.924724 | AL32: =AK32-CO32+CP32 -> 12.207064 | AM32: =AL32-CQ32+CR32 -> 14.36117 | AN32: =AM32-CS32+CT32 -> 15.64351 | AO32: =AN32-CU32+CV32 -> 10.334945 | AP32: =AO32-CW32+CX32 -> 5.4859108 | AQ32: =AP32-CY32+CZ32 -> -1.4882172 | AS32: =$H$32*月別販売比率!AG5 -> 8.71766 | AU32: =$H$32*月別販売比率!AL5 -> 7.845894 | AW32: =$H$32*月別販売比率!AQ5 -> 8.71766 | AX32: 15 | AY32: =$H$32*月別販売比率!AV5 -> 5.3085646 | AZ32: 12 | BA32: =$H$32*月別販売比率!BA5 -> 4.8490346 | BB32: 12 | BC32: =$H$32*月別販売比率!BF5 -> 6.974128 | BE32: =$H$32*月別販売比率!C21 -> 6.1777045 | BF32: 24 | BG32: =$H$32*月別販売比率!H21 -> 6.102362 | BI32: =$H$32*月別販売比率!M21 -> 8.8103888 | BK32: =$H$32*月別販売比率!R21 -> 6.974128 | BL32: 10 | BM32: =$H$32*月別販売比率!W21 -> 6.6399557 | BO32: =$H$32*月別販売比率!AB21 -> 10.461192 | BP32: 30 | BQ32: =$H$32*月別販売比率!AG21 -> 8.71766 | BS32: =$H$32*月別販売比率!AL21 -> 7.845894 | BT32: 0 | BU32: =$H$32*月別販売比率!AQ21 -> 8.71766 | BW32: =$H$32*月別販売比率!AV21 -> 5.3085646 | BX32: 12 | BY32: =$H$32*月別販売比率!BA21 -> 4.8490346 | CA32: =$H$32*月別販売比率!BF21 -> 6.974128 | CC32: =H32*月別販売比率!$C$21 -> 6.1777045 | CE32: =H32*月別販売比率!$H$21 -> 6.102362 | CF32: 22 | CG32: =H32*月別販売比率!$M$21 -> 8.8103888 | CI32: =H32*月別販売比率!$R$21 -> 6.974128 | CK32: =H32*月別販売比率!$W$21 -> 6.6399557 | CL32: 20 | CM32: =H32*月別販売比率!$AB$21 -> 10.461192 | CO32: =H32*月別販売比率!$AG$21 -> 8.71766 | CQ32: =H32*月別販売比率!$AL$21 -> 7.845894 | CR32: 10 | CS32: =H32*月別販売比率!$AQ$21 -> 8.71766 | CT32: 10 | CU32: =H32*月別販売比率!$AV$21 -> 5.3085646 | CW32: =H32*月別販売比率!$BA$21 -> 4.8490346 | CY32: =H32*月別販売比率!$BF$21 -> 6.974128
D33: 2 | E33: +1.00 | F33: 76 | G33: =F33*3630 -> 275880 | H33: =F33*($H$27/$F$27) -> 389.73068 | I33: =H33*3630 -> 1414722.4 | J33: 68 | K33: =SUM(L33:N33) -> 23 | L33: 1 | M33: 22 | T33: 45721 | X33: 45869 | AI33: =SUM(J33:K33)-CI33+CJ33 -> 59.821545 | AJ33: =AI33-CK33+CL33 -> 80.137037 | AK33: =AJ33-CM33+CN33 -> 33.369355 | AL33: =AK33-CO33+CP33 -> 34.396287 | AM33: =AL33-CQ33+CR33 -> 54.320525 | AN33: =AM33-CS33+CT33 -> 70.347457 | AO33: =AN33-CU33+CV33 -> 46.61505 | AP33: =AO33-CW33+CX33 -> 24.937013 | AQ33: =AP33-CY33+CZ33 -> -6.2414416 | AS33: =$H$33*月別販売比率!AG5 -> 38.973068 | AU33: =$H$33*月別販売比率!AL5 -> 35.075762 | AW33: =$H$33*月別販売比率!AQ5 -> 38.973068 | AX33: 45 | AY33: =$H$33*月別販売比率!AV5 -> 23.732407 | AZ33: 42 | BA33: =$H$33*月別販売比率!BA5 -> 21.678037 | BB33: 42 | BC33: =$H$33*月別販売比率!BF5 -> 31.178455 | BE33: =$H$33*月別販売比率!C21 -> 27.617973 | BF33: 45 | BG33: =$H$33*月別販売比率!H21 -> 27.281148 | BI33: =$H$33*月別販売比率!M21 -> 39.387621 | BJ33: 75 | BK33: =$H$33*月別販売比率!R21 -> 31.178455 | BL33: 110 | BM33: =$H$33*月別販売比率!W21 -> 29.684508 | BO33: =$H$33*月別販売比率!AB21 -> 46.767682 | BP33: 100 | BQ33: =$H$33*月別販売比率!AG21 -> 38.973068 | BS33: =$H$33*月別販売比率!AL21 -> 35.075762 | BT33: 60 | BU33: =$H$33*月別販売比率!AQ21 -> 38.973068 | BW33: =$H$33*月別販売比率!AV21 -> 23.732407 | BX33: 110 | BY33: =$H$33*月別販売比率!BA21 -> 21.678037 | CA33: =$H$33*月別販売比率!BF21 -> 31.178455 | CC33: =H33*月別販売比率!$C$21 -> 27.617973 | CE33: =H33*月別販売比率!$H$21 -> 27.281148 | CF33: 77 | CG33: =H33*月別販売比率!$M$21 -> 39.387621 | CI33: =H33*月別販売比率!$R$21 -> 31.178455 | CK33: =H33*月別販売比率!$W$21 -> 29.684508 | CL33: 50 | CM33: =H33*月別販売比率!$AB$21 -> 46.767682 | CO33: =H33*月別販売比率!$AG$21 -> 38.973068 | CP33: 40 | CQ33: =H33*月別販売比率!$AL$21 -> 35.075762 | CR33: 55 | CS33: =H33*月別販売比率!$AQ$21 -> 38.973068 | CT33: 55 | CU33: =H33*月別販売比率!$AV$21 -> 23.732407 | CW33: =H33*月別販売比率!$BA$21 -> 21.678037 | CY33: =H33*月別販売比率!$BF$21 -> 31.178455
E34: +1.50 | F34: 94 | G34: =F34*3630 -> 341220 | H34: =F34*($H$27/$F$27) -> 482.03532 | I34: =H34*3630 -> 1749788.2 | J34: 142 | K34: =SUM(L34:N34) -> 24 | L34: 6 | M34: 18 | R34: 45685 | X34: 45856 | AI34: =SUM(J34:K34)-CI34+CJ34 -> 127.43717 | AJ34: =AI34-CK34+CL34 -> 140.72212 | AK34: =AJ34-CM34+CN34 -> 82.877887 | AL34: =AK34-CO34+CP34 -> 74.674355 | AM34: =AL34-CQ34+CR34 -> 81.291176 | AN34: =AM34-CS34+CT34 -> 88.087644 | AO34: =AN34-CU34+CV34 -> 58.734404 | AP34: =AO34-CW34+CX34 -> 31.922095 | AQ34: =AP34-CY34+CZ34 -> -6.6407304 | AS34: =$H$34*月別販売比率!AG5 -> 48.203532 | AU34: =$H$34*月別販売比率!AL5 -> 43.383179 | AW34: =$H$34*月別販売比率!AQ5 -> 48.203532 | AX34: 45 | AY34: =$H$34*月別販売比率!AV5 -> 29.35324 | AZ34: 48 | BA34: =$H$34*月別販売比率!BA5 -> 26.812309 | BB34: 48 | BC34: =$H$34*月別販売比率!BF5 -> 38.562826 | BE34: =$H$34*月別販売比率!C21 -> 34.159072 | BF34: 60 | BG34: =$H$34*月別販売比率!H21 -> 33.742472 | BI34: =$H$34*月別販売比率!M21 -> 48.716268 | BJ34: 95 | BK34: =$H$34*月別販売比率!R21 -> 38.562826 | BL34: 130 | BM34: =$H$34*月別販売比率!W21 -> 36.715049 | BO34: =$H$34*月別販売比率!AB21 -> 57.844238 | BP34: 125 | BQ34: =$H$34*月別販売比率!AG21 -> 48.203532 | BS34: =$H$34*月別販売比率!AL21 -> 43.383179 | BT34: 55 | BU34: =$H$34*月別販売比率!AQ21 -> 48.203532 | BW34: =$H$34*月別販売比率!AV21 -> 29.35324 | BX34: 120 | BY34: =$H$34*月別販売比率!BA21 -> 26.812309 | CA34: =$H$34*月別販売比率!BF21 -> 38.562826 | CC34: =H34*月別販売比率!$C$21 -> 34.159072 | CE34: =H34*月別販売比率!$H$21 -> 33.742472 | CF34: 97 | CG34: =H34*月別販売比率!$M$21 -> 48.716268 | CI34: =H34*月別販売比率!$R$21 -> 38.562826 | CK34: =H34*月別販売比率!$W$21 -> 36.715049 | CL34: 50 | CM34: =H34*月別販売比率!$AB$21 -> 57.844238 | CO34: =H34*月別販売比率!$AG$21 -> 48.203532 | CP34: 40 | CQ34: =H34*月別販売比率!$AL$21 -> 43.383179 | CR34: 50 | CS34: =H34*月別販売比率!$AQ$21 -> 48.203532 | CT34: 55 | CU34: =H34*月別販売比率!$AV$21 -> 29.35324 | CW34: =H34*月別販売比率!$BA$21 -> 26.812309 | CY34: =H34*月別販売比率!$BF$21 -> 38.562826
E35: +2.00 | F35: 96 | G35: =F35*3630 -> 348480 | H35: =F35*($H$27/$F$27) -> 492.29139 | I35: =H35*3630 -> 1787017.7 | J35: 194 | K35: =SUM(L35:N35) -> 31 | L35: 10 | M35: 21 | Q35: 45631 | R35: 45685 | AB35: 45971 | AC35: 45971 | AI35: =SUM(J35:K35)-CI35+CJ35 -> 185.61669 | AJ35: =AI35-CK35+CL35 -> 188.12047 | AK35: =AJ35-CM35+CN35 -> 129.0455 | AL35: =AK35-CO35+CP35 -> 119.81636 | AM35: =AL35-CQ35+CR35 -> 105.51014 | AN35: =AM35-CS35+CT35 -> 111.281 | AO35: =AN35-CU35+CV35 -> 81.303221 | AP35: =AO35-CW35+CX35 -> 53.920438 | AQ35: =AP35-CY35+CZ35 -> 14.537126 | AS35: =$H$35*月別販売比率!AG5 -> 49.229139 | AU35: =$H$35*月別販売比率!AL5 -> 44.306225 | AW35: =$H$35*月別販売比率!AQ5 -> 49.229139 | AX35: 45 | AY35: =$H$35*月別販売比率!AV5 -> 29.977777 | AZ35: 36 | BA35: =$H$35*月別販売比率!BA5 -> 27.382783 | BB35: 36 | BC35: =$H$35*月別販売比率!BF5 -> 39.383311 | BE35: =$H$35*月別販売比率!C21 -> 34.885861 | BF35: 70 | BG35: =$H$35*月別販売比率!H21 -> 34.460397 | BI35: =$H$35*月別販売比率!M21 -> 49.752784 | BJ35: 90 | BK35: =$H$35*月別販売比率!R21 -> 39.383311 | BL35: 140 | BM35: =$H$35*月別販売比率!W21 -> 37.496221 | BO35: =$H$35*月別販売比率!AB21 -> 59.074967 | BP35: 115 | BQ35: =$H$35*月別販売比率!AG21 -> 49.229139 | BS35: =$H$35*月別販売比率!AL21 -> 44.306225 | BT35: 40 | BU35: =$H$35*月別販売比率!AQ21 -> 49.229139 | BW35: =$H$35*月別販売比率!AV21 -> 29.977777 | BX35: 120 | BY35: =$H$35*月別販売比率!BA21 -> 27.382783 | CA35: =$H$35*月別販売比率!BF21 -> 39.383311 | CC35: =H35*月別販売比率!$C$21 -> 34.885861 | CE35: =H35*月別販売比率!$H$21 -> 34.460397 | CF35: 47 | CG35: =H35*月別販売比率!$M$21 -> 49.752784 | CI35: =H35*月別販売比率!$R$21 -> 39.383311 | CK35: =H35*月別販売比率!$W$21 -> 37.496221 | CL35: 40 | CM35: =H35*月別販売比率!$AB$21 -> 59.074967 | CO35: =H35*月別販売比率!$AG$21 -> 49.229139 | CP35: 40 | CQ35: =H35*月別販売比率!$AL$21 -> 44.306225 | CR35: 30 | CS35: =H35*月別販売比率!$AQ$21 -> 49.229139 | CT35: 55 | CU35: =H35*月別販売比率!$AV$21 -> 29.977777 | CW35: =H35*月別販売比率!$BA$21 -> 27.382783 | CY35: =H35*月別販売比率!$BF$21 -> 39.383311
E36: +2.50 | F36: 31 | G36: =F36*3630 -> 112530 | H36: =F36*($H$27/$F$27) -> 158.96909 | I36: =H36*3630 -> 577057.81 | J36: 49 | K36: =SUM(L36:N36) -> 22 | L36: 8 | M36: 14 | Q36: 45631 | AI36: =SUM(J36:K36)-CI36+CJ36 -> 58.282472 | AJ36: =AI36-CK36+CL36 -> 46.174318 | AK36: =AJ36-CM36+CN36 -> 27.098026 | AL36: =AK36-CO36+CP36 -> 11.201117 | AM36: =AL36-CQ36+CR36 -> 21.893898 | AN36: =AM36-CS36+CT36 -> 30.996989 | AO36: =AN36-CU36+CV36 -> 21.316665 | AP36: =AO36-CW36+CX36 -> 12.474308 | AQ36: =AP36-CY36+CZ36 -> -0.24321961 | AS36: =$H$36*月別販売比率!AG5 -> 15.896909 | AU36: =$H$36*月別販売比率!AL5 -> 14.307219 | AW36: =$H$36*月別販売比率!AQ5 -> 15.896909 | AX36: 25 | AY36: =$H$36*月別販売比率!AV5 -> 9.6803238 | AZ36: 12 | BA36: =$H$36*月別販売比率!BA5 -> 8.8423572 | BB36: 12 | BC36: =$H$36*月別販売比率!BF5 -> 12.717528 | BE36: =$H$36*月別販売比率!C21 -> 11.265226 | BF36: 43 | BG36: =$H$36*月別販売比率!H21 -> 11.127837 | BI36: =$H$36*月別販売比率!M21 -> 16.066003 | BJ36: 10 | BK36: =$H$36*月別販売比率!R21 -> 12.717528 | BL36: 30 | BM36: =$H$36*月別販売比率!W21 -> 12.108155 | BO36: =$H$36*月別販売比率!AB21 -> 19.076291 | BP36: 45 | BQ36: =$H$36*月別販売比率!AG21 -> 15.896909 | BS36: =$H$36*月別販売比率!AL21 -> 14.307219 | BT36: 15 | BU36: =$H$36*月別販売比率!AQ21 -> 15.896909 | BW36: =$H$36*月別販売比率!AV21 -> 9.6803238 | BX36: 45 | BY36: =$H$36*月別販売比率!BA21 -> 8.8423572 | CA36: =$H$36*月別販売比率!BF21 -> 12.717528 | CC36: =H36*月別販売比率!$C$21 -> 11.265226 | CE36: =H36*月別販売比率!$H$21 -> 11.127837 | CF36: 42 | CG36: =H36*月別販売比率!$M$21 -> 16.066003 | CI36: =H36*月別販売比率!$R$21 -> 12.717528 | CK36: =H36*月別販売比率!$W$21 -> 12.108155 | CM36: =H36*月別販売比率!$AB$21 -> 19.076291 | CO36: =H36*月別販売比率!$AG$21 -> 15.896909 | CQ36: =H36*月別販売比率!$AL$21 -> 14.307219 | CR36: 25 | CS36: =H36*月別販売比率!$AQ$21 -> 15.896909 | CT36: 25 | CU36: =H36*月別販売比率!$AV$21 -> 9.6803238 | CW36: =H36*月別販売比率!$BA$21 -> 8.8423572 | CY36: =H36*月別販売比率!$BF$21 -> 12.717528
